Workbook

Sheet Total
A1: Sample | B1: cmbs | C1: Age R396 x 1000 | D1: Pt counted | E1: Pt total | F1: Fragments count (estimate) | G1: Fragment ratio | H1: Transparent ratio | I1: Gram sediment | J1: Pt per gram sediment | K1: p/pb ratio
A2: 9-105 | B2: 101 | C2: 10.298053 | D2: {=SUM('250-600 μm'!D2:Z2+'150-250 μm '!D2:Z2+'150-600 μm (rest)'!D2:Z2)} -> 4 | E2: =D2 -> 4 | F2: 2 | G2: =F2/(D2+F2) -> 0.33333333 | H2: =Species!AN2 -> 0 | I2: 8.26 | J2: =ROUND(E2/I2,2) -> 0.48 | K2: 50.6
A3: 9-015 | B3: 191 | C3: 11.768078 | D3: {=SUM('250-600 μm'!D3:Z3+'150-250 μm '!D3:Z3+'150-600 μm (rest)'!D3:Z3)} -> 73 | E3: =D3 -> 73 | F3: 17 | G3: =F3/(D3+F3) -> 0.18888889 | H3: =Species!AN3 -> 0.20547945 | I3: 9.91 | J3: =ROUND(E3/I3,2) -> 7.37 | K3: 58
A4: 8-145 | B4: 211 | C4: 12.140505 | D4: {=SUM('250-600 μm'!D4:Z4+'150-250 μm '!D4:Z4+'150-600 μm (rest)'!D4:Z4)} -> 59 | E4: =D4 -> 59 | F4: 22 | G4: =F4/(D4+F4) -> 0.27160494 | H4: =Species!AN4 -> 0.06779661 | I4: 12.13 | J4: =ROUND(E4/I4,2) -> 4.86 | K4: 50.2
A5: 8-075 | B5: 281 | C5: 12.681927 | D5: {=SUM('250-600 μm'!D5:Z5+'150-250 μm '!D5:Z5+'150-600 μm (rest)'!D5:Z5)} -> 29 | E5: =D5+70 -> 99 | F5: 8 | G5: =F5/(D5+F5) -> 0.21621622 | H5: =Species!AN5 -> 0.13793103 | I5: 10.47 | J5: =ROUND(E5/I5,2) -> 9.46 | K5: 46.9
A6: 8-020 | B6: 336 | C6: 12.90434 | D6: {=SUM('250-600 μm'!D6:Z6+'150-250 μm '!D6:Z6+'150-600 μm (rest)'!D6:Z6)} -> 118 | E6: =ROUND(D6*(32/11),2) -> 343.27 | F6: 34 | G6: =F6/(D6+F6) -> 0.22368421 | H6: =Species!AN6 -> 0.24576271 | I6: 13.45 | J6: =ROUND(E6/I6,2) -> 25.52 | K6: 78.5
A7: 7-025 | B7: 482 | C7: 13.4115 | D7: {=SUM('250-600 μm'!D7:Z7+'150-250 μm '!D7:Z7+'150-600 μm (rest)'!D7:Z7)} -> 18 | E7: =D7 -> 18 | F7: 15 | G7: =F7/(D7+F7) -> 0.45454545 | H7: =Species!AN7 -> 0.055555556 | I7: 13.7 | J7: =ROUND(E7/I7,2) -> 1.31 | K7: 84.2
A8: 6a-075 | B8: 542 | C8: 15.297745 | D8: {=SUM('250-600 μm'!D8:Z8+'150-250 μm '!D8:Z8+'150-600 μm (rest)'!D8:Z8)} -> 149 | E8: =ROUND(D8*(256/31),2) -> 1230.45 | F8: 48 | G8: =F8/(D8+F8) -> 0.24365482 | H8: =Species!AN8 -> 0.32214765 | I8: 13.66 | J8: =ROUND(E8/I8,2) -> 90.08 | K8: 84.1
A9: 6a-010 | B9: 607 | C9: 17.630333 | D9: {=SUM('250-600 μm'!D9:Z9+'150-250 μm '!D9:Z9+'150-600 μm (rest)'!D9:Z9)} -> 16 | E9: =D9 -> 16 | F9: 13 | G9: =F9/(D9+F9) -> 0.44827586 | H9: =Species!AN9 -> 0.0625 | I9: 12.89 | J9: =ROUND(E9/I9,2) -> 1.24 | K9: 11
A10: 6-125 | B10: 641 | C10: 19.789979 | D10: {=SUM('250-600 μm'!D10:Z10+'150-250 μm '!D10:Z10+'150-600 μm (rest)'!D10:Z10)} -> 34 | E10: =D10 -> 34 | F10: 12 | G10: =F10/(D10+F10) -> 0.26086957 | H10: =Species!AN10 -> 0.23529412 | I10: 12.82 | J10: =ROUND(E10/I10,2) -> 2.65 | K10: 64.1
A11: 6-090 | B11: 676 | C11: 22.102144 | D11: {=SUM('250-600 μm'!D11:Z11+'150-250 μm '!D11:Z11+'150-600 μm (rest)'!D11:Z11)} -> 31 | E11: =D11 -> 31 | F11: 20 | G11: =F11/(D11+F11) -> 0.39215686 | H11: =Species!AN11 -> 0.16129032 | I11: 16.08 | J11: =ROUND(E11/I11,2) -> 1.93 | K11: 63.3
A12: 6-020 | B12: 746 | C12: 26.142462 | D12: {=SUM('250-600 μm'!D12:Z12+'150-250 μm '!D12:Z12+'150-600 μm (rest)'!D12:Z12)} -> 167 | E12: =D12 -> 167 | F12: 94 | G12: =F12/(D12+F12) -> 0.36015326 | H12: =Species!AN12 -> 0.31736527 | I12: 19.41 | J12: =ROUND(E12/I12,2) -> 8.6 | K12: 65.6
A13: 4-060 | B13: 833 | C13: 29.476255 | D13: {=SUM('250-600 μm'!D13:Z13+'150-250 μm '!D13:Z13+'150-600 μm (rest)'!D13:Z13)} -> 2 | E13: =D13 -> 2 | F13: 6 | G13: =F13/(D13+F13) -> 0.75 | H13: =Species!AN13 -> 0 | I13: 14.7 | J13: =ROUND(E13/I13,2) -> 0.14 | K13: 30.4
A14: 4-005 | B14: 888 | C14: 30.863619 | D14: {=SUM('250-600 μm'!D14:Z14+'150-250 μm '!D14:Z14+'150-600 μm (rest)'!D14:Z14)} -> 3 | E14: =D14 -> 3 | F14: 8 | G14: =F14/(D14+F14) -> 0.72727273 | H14: =Species!AN14 -> 0 | I14: 15.63 | J14: =ROUND(E14/I14,2) -> 0.19 | K14: 49.5
A15: 3-031 | B15: 940 | C15: 31.496038 | D15: {=SUM('250-600 μm'!D15:Z15+'150-250 μm '!D15:Z15+'150-600 μm (rest)'!D15:Z15)} -> 0 | E15: =D15 -> 0 | F15: 0 | G15: 0 | H15: =Species!AN15 -> 0 | I15: 15.4 | J15: =E15/I15 -> 0 | K15: 48.4
A16: 2-025 | B16: 1021 | C16: 33.121 | D16: {=SUM('250-600 μm'!D16:Z16+'150-250 μm '!D16:Z16+'150-600 μm (rest)'!D16:Z16)} -> 0 | E16: =D16 -> 0 | F16: 5 | G16: =F16/(D16+F16) -> 1 | H16: =Species!AN16 -> 0 | I16: 15.96 | J16: =E16/I16 -> 0 | K16: 67
I19: {=SUM(J10:J16/7)} -> 1.93

Sheet 250-600 μm
A1: Sample | B1: cmbs | C1: Age R396 x 1000 | D1: Heliconoides inflatus | E1: Heliconoides inflatus (transparent) | F1: Limacina trochiformis | G1: Limacina trochiformis (transparent) | H1: Limacina retroversa | I1: Limacina retroversa (transparent) | J1: Limacina retroversa (striata) | K1: Limacina bulimoides | L1: Limacina bulimoides (transparent) | M1: Limacina bulimoides (striata) | N1: Creseis sp. | O1: Creseis sp. (transparent) | P1: Creseis conica | Q1: Creseis conica (transparent) | R1: Creseis acicula | S1: Creseis acicula (transparent) | T1: Clio cuspidata | U1: Clio cuspidata (transparent) | V1: Clio pyramidata | W1: Clio pyramidata (transparent) | X1: Cavolinia sp. | Y1: Cavolinia sp. (transparent) | Z1: Clionidarum | AA1: Total
A2: 9-105 | B2: 101 | C2: 10.298053 | D2: 0 | E2: 0 | F2: 0 | G2: 0 | H2: 0 | I2: 0 | J2: 0 | K2: 0 | L2: 0 | M2: 0 | N2: 0 | O2: 0 | P2: 0 | Q2: 0 | R2: 0 | S2: 0 | T2: 0 | U2: 0 | V2: 0 | W2: 0 | X2: 0 | Y2: 0 | Z2: 0 | AA2: =SUM(D2:Z2) -> 0
A3: 9-015 | B3: 191 | C3: 11.768078 | D3: 9 | E3: 3 | F3: 3 | G3: 1 | H3: 0 | I3: 0 | J3: 0 | K3: 0 | L3: 0 | M3: 0 | N3: 0 | O3: 0 | P3: 0 | Q3: 0 | R3: 0 | S3: 0 | T3: 0 | U3: 0 | V3: 0 | W3: 0 | X3: 1 | Y3: 0 | Z3: 0 | AA3: =SUM(D3:Z3) -> 17
A4: 8-145 | B4: 211 | C4: 12.140505 | D4: 1 | E4: 0 | F4: 4 | G4: 0 | H4: 1 | I4: 0 | J4: 0 | K4: 0 | L4: 0 | M4: 0 | N4: 0 | O4: 0 | P4: 0 | Q4: 0 | R4: 0 | S4: 0 | T4: 0 | U4: 0 | V4: 0 | W4: 0 | X4: 2 | Y4: 0 | Z4: 0 | AA4: =SUM(D4:Z4) -> 8
A5: 8-075 | B5: 281 | C5: 12.681927 | D5: 1 | E5: 0 | F5: 1 | G5: 0 | H5: 0 | I5: 0 | J5: 1 | K5: 0 | L5: 0 | M5: 0 | N5: 0 | O5: 0 | P5: 0 | Q5: 0 | R5: 0 | S5: 0 | T5: 0 | U5: 0 | V5: 0 | W5: 0 | X5: 0 | Y5: 0 | Z5: 0 | AA5: =SUM(D5:Z5) -> 3
A6: 8-020 | B6: 336 | C6: 12.90434 | D6: 0 | E6: 0 | F6: 0 | G6: 0 | H6: 0 | I6: 0 | J6: 0 | K6: 0 | L6: 0 | M6: 0 | N6: 0 | O6: 0 | P6: 2 | Q6: 0 | R6: 0 | S6: 0 | T6: 0 | U6: 0 | V6: 0 | W6: 0 | X6: 1 | Y6: 0 | Z6: 0 | AA6: =SUM(D6:Z6) -> 3
A7: 7-025 | B7: 482 | C7: 13.4115 | D7: 0 | E7: 0 | F7: 0 | G7: 0 | H7: 0 | I7: 0 | J7: 0 | K7: 0 | L7: 0 | M7: 0 | N7: 0 | O7: 0 | P7: 0 | Q7: 0 | R7: 0 | S7: 0 | T7: 0 | U7: 0 | V7: 0 | W7: 0 | X7: 0 | Y7: 0 | Z7: 0 | AA7: =SUM(D7:Z7) -> 0
A8: 6a-075 | B8: 542 | C8: 15.297745 | D8: 6 | E8: 1 | F8: 1 | G8: 0 | H8: 0 | I8: 0 | J8: 0 | K8: 0 | L8: 0 | M8: 0 | N8: 0 | O8: 0 | P8: 1 | Q8: 0 | R8: 0 | S8: 0 | T8: 0 | U8: 0 | V8: 0 | W8: 0 | X8: 0 | Y8: 0 | Z8: 0 | AA8: =SUM(D8:Z8) -> 9
A9: 6a-010 | B9: 607 | C9: 17.630333 | D9: 0 | E9: 0 | F9: 1 | G9: 0 | H9: 0 | I9: 0 | J9: 0 | K9: 0 | L9: 0 | M9: 0 | N9: 0 | O9: 0 | P9: 0 | Q9: 0 | R9: 0 | S9: 0 | T9: 0 | U9: 0 | V9: 0 | W9: 0 | X9: 0 | Y9: 0 | Z9: 0 | AA9: =SUM(D9:Z9) -> 1
A10: 6-125 | B10: 641 | C10: 19.789979 | D10: 0 | E10: 0 | F10: 0 | G10: 0 | H10: 0 | I10: 0 | J10: 0 | K10: 0 | L10: 0 | M10: 0 | N10: 0 | O10: 0 | P10: 0 | Q10: 0 | R10: 0 | S10: 0 | T10: 0 | U10: 0 | V10: 0 | W10: 0 | X10: 0 | Y10: 0 | Z10: 0 | AA10: =SUM(D10:Z10) -> 0
A11: 6-090 | B11: 676 | C11: 22.102144 | D11: 0 | E11: 0 | F11: 0 | G11: 0 | H11: 0 | I11: 0 | J11: 0 | K11: 0 | L11: 0 | M11: 0 | N11: 0 | O11: 0 | P11: 0 | Q11: 0 | R11: 0 | S11: 0 | T11: 0 | U11: 0 | V11: 0 | W11: 0 | X11: 0 | Y11: 0 | Z11: 0 | AA11: =SUM(D11:Z11) -> 0
A12: 6-020 | B12: 746 | C12: 26.142462 | D12: 2 | E12: 0 | F12: 0 | G12: 0 | H12: 0 | I12: 0 | J12: 0 | K12: 0 | L12: 0 | M12: 0 | N12: 0 | O12: 0 | P12: 0 | Q12: 0 | R12: 0 | S12: 0 | T12: 0 | U12: 0 | V12: 0 | W12: 0 | X12: 0 | Y12: 0 | Z12: 0 | AA12: =SUM(D12:Z12) -> 2
A13: 4-060 | B13: 833 | C13: 29.476255 | D13: 0 | E13: 0 | F13: 0 | G13: 0 | H13: 0 | I13: 0 | J13: 0 | K13: 0 | L13: 0 | M13: 0 | N13: 0 | O13: 0 | P13: 0 | Q13: 0 | R13: 0 | S13: 0 | T13: 0 | U13: 0 | V13: 0 | W13: 0 | X13: 0 | Y13: 0 | Z13: 0 | AA13: =SUM(D13:Z13) -> 0
... A16: 2-025 | B16: 1021 | C16: 33.121 | D16: 0 | E16: 0 | F16: 0 | G16: 0 | H16: 0 | I16: 0 | J16: 0 | K16: 0 | L16: 0 | M16: 0 | N16: 0 | O16: 0 | P16: 0 | Q16: 0 | R16: 0 | S16: 0 | T16: 0 | U16: 0 | V16: 0 | W16: 0 | X16: 0 | Y16: 0 | Z16: 0 | AA16: =SUM(D16:Z16) -> 0

Sheet 150-250 μm 
A1: Sample | B1: cmbs | C1: Age R396 x 1000 | D1: Heliconoides inflatus | E1: Heliconoides inflatus (transparent) | F1: Limacina trochiformis | G1: Limacina trochiformis (transparent) | H1: Limacina retroversa | I1: Limacina retroversa (transparent) | J1: Limacina retroversa (striata) | K1: Limacina bulimoides | L1: Limacina bulimoides (transparent) | M1: Limacina bulimoides (striata) | N1: Creseis sp. | O1: Creseis sp. (transparent) | P1: Creseis conica | Q1: Creseis conica (transparent) | R1: Creseis acicula | S1: Creseis acicula (transparent) | T1: Clio cuspidata | U1: Clio cuspidata (transparent) | V1: Clio pyramidata | W1: Clio pyramidata (transparent) | X1: Cavolinia sp. | Y1: Cavolinia sp. (transparent) | Z1: Clionidarum | AA1: Total
A2: 9-105 | B2: 101 | C2: 10.298053 | D2: 1 | E2: 0 | F2: 1 | G2: 0 | H2: 0 | I2: 0 | J2: 0 | K2: 0 | L2: 0 | M2: 0 | N2: 0 | O2: 0 | P2: 0 | Q2: 0 | R2: 0 | S2: 0 | T2: 1 | U2: 0 | V2: 0 | W2: 0 | X2: 1 | Y2: 0 | Z2: 0 | AA2: =SUM(D2:Z2) -> 4
A3: 9-015 | B3: 191 | C3: 11.768078 | D3: 9 | E3: 6 | F3: 31 | G3: 5 | H3: 2 | I3: 0 | J3: 0 | K3: 0 | L3: 0 | M3: 0 | N3: 0 | O3: 0 | P3: 3 | Q3: 0 | R3: 0 | S3: 0 | T3: 0 | U3: 0 | V3: 0 | W3: 0 | X3: 0 | Y3: 0 | Z3: 0 | AA3: =SUM(D3:Z3) -> 56
A4: 8-145 | B4: 211 | C4: 12.140505 | D4: 7 | E4: 0 | F4: 32 | G4: 2 | H4: 3 | I4: 0 | J4: 0 | K4: 0 | L4: 0 | M4: 0 | N4: 0 | O4: 0 | P4: 1 | Q4: 0 | R4: 1 | S4: 2 | T4: 1 | U4: 0 | V4: 0 | W4: 0 | X4: 2 | Y4: 0 | Z4: 0 | AA4: =SUM(D4:Z4) -> 51
A5: 8-075 | B5: 281 | C5: 12.681927 | D5: 1 | E5: 0 | F5: 5 | G5: 0 | H5: 0 | I5: 0 | J5: 0 | K5: 0 | L5: 0 | M5: 0 | N5: 0 | O5: 0 | P5: 1 | Q5: 0 | R5: 0 | S5: 0 | T5: 1 | U5: 0 | V5: 0 | W5: 0 | X5: 1 | Y5: 0 | Z5: 0 | AA5: =SUM(D5:Z5) -> 9
A6: 8-020 | B6: 336 | C6: 12.90434 | D6: 2 | E6: 1 | F6: 14 | G6: 12 | H6: 0 | I6: 0 | J6: 0 | K6: 0 | L6: 0 | M6: 0 | N6: 0 | O6: 0 | P6: 2 | Q6: 3 | R6: 1 | S6: 0 | T6: 1 | U6: 0 | V6: 0 | W6: 0 | X6: 0 | Y6: 0 | Z6: 0 | AA6: =SUM(D6:Z6) -> 36
A7: 7-025 | B7: 482 | C7: 13.4115 | D7: 0 | E7: 0 | F7: 0 | G7: 0 | H7: 0 | I7: 0 | J7: 0 | K7: 0 | L7: 0 | M7: 0 | N7: 0 | O7: 0 | P7: 0 | Q7: 0 | R7: 0 | S7: 0 | T7: 0 | U7: 0 | V7: 0 | W7: 0 | X7: 0 | Y7: 0 | Z7: 0 | AA7: =SUM(D7:Z7) -> 0
A8: 6a-075 | B8: 542 | C8: 15.297745 | D8: 31 | E8: 13 | F8: 8 | G8: 1 | H8: 1 | I8: 0 | J8: 0 | K8: 0 | L8: 0 | M8: 0 | N8: 0 | O8: 0 | P8: 2 | Q8: 2 | R8: 0 | S8: 0 | T8: 0 | U8: 0 | V8: 0 | W8: 0 | X8: 3 | Y8: 0 | Z8: 0 | AA8: =SUM(D8:Z8) -> 61
A9: 6a-010 | B9: 607 | C9: 17.630333 | D9: 5 | E9: 0 | F9: 2 | G9: 0 | H9: 0 | I9: 0 | J9: 0 | K9: 0 | L9: 0 | M9: 0 | N9: 0 | O9: 0 | P9: 0 | Q9: 0 | R9: 0 | S9: 0 | T9: 0 | U9: 0 | V9: 0 | W9: 0 | X9: 0 | Y9: 0 | Z9: 0 | AA9: =SUM(D9:Z9) -> 7
A10: 6-125 | B10: 641 | C10: 19.789979 | D10: 0 | E10: 0 | F10: 0 | G10: 0 | H10: 0 | I10: 0 | J10: 0 | K10: 0 | L10: 0 | M10: 0 | N10: 0 | O10: 0 | P10: 0 | Q10: 0 | R10: 0 | S10: 0 | T10: 0 | U10: 0 | V10: 0 | W10: 0 | X10: 0 | Y10: 0 | Z10: 0 | AA10: =SUM(D10:Z10) -> 0
A11: 6-090 | B11: 676 | C11: 22.102144 | D11: 0 | E11: 0 | F11: 0 | G11: 0 | H11: 0 | I11: 0 | J11: 0 | K11: 0 | L11: 0 | M11: 0 | N11: 0 | O11: 0 | P11: 0 | Q11: 0 | R11: 0 | S11: 0 | T11: 0 | U11: 0 | V11: 0 | W11: 0 | X11: 0 | Y11: 0 | Z11: 0 | AA11: =SUM(D11:Z11) -> 0
A12: 6-020 | B12: 746 | C12: 26.142462 | D12: 3 | E12: 0 | F12: 1 | G12: 0 | H12: 0 | I12: 0 | J12: 0 | K12: 0 | L12: 0 | M12: 0 | N12: 0 | O12: 0 | P12: 1 | Q12: 0 | R12: 0 | S12: 0 | T12: 0 | U12: 0 | V12: 0 | W12: 0 | X12: 1 | Y12: 0 | Z12: 0 | AA12: =SUM(D12:Z12) -> 6
A13: 4-060 | B13: 833 | C13: 29.476255 | D13: 0 | E13: 0 | F13: 1 | G13: 0 | H13: 0 | I13: 0 | J13: 0 | K13: 0 | L13: 0 | M13: 0 | N13: 0 | O13: 0 | P13: 0 | Q13: 0 | R13: 0 | S13: 0 | T13: 0 | U13: 0 | V13: 0 | W13: 0 | X13: 0 | Y13: 0 | Z13: 0 | AA13: =SUM(D13:Z13) -> 1
... A16: 2-025 | B16: 1021 | C16: 33.121 | D16: 0 | E16: 0 | F16: 0 | G16: 0 | H16: 0 | I16: 0 | J16: 0 | K16: 0 | L16: 0 | M16: 0 | N16: 0 | O16: 0 | P16: 0 | Q16: 0 | R16: 0 | S16: 0 | T16: 0 | U16: 0 | V16: 0 | W16: 0 | X16: 0 | Y16: 0 | Z16: 0 | AA16: =SUM(D16:Z16) -> 0

Sheet 150-600 μm (rest)
A1: Sample | B1: cmbs | C1: Age R396 x 1000 | D1: Heliconoides inflatus | E1: Heliconoides inflatus (transparent) | F1: Limacina trochiformis | G1: Limacina trochiformis (transparent) | H1: Limacina retroversa | I1: Limacina retroversa (transparent) | J1: Limacina retroversa (striata) | K1: Limacina bulimoides | L1: Limacina bulimoides (transparent) | M1: Limacina bulimoides (striata) | N1: Creseis sp. | O1: Creseis sp. (transparent) | P1: Creseis conica | Q1: Creseis conica (transparent) | R1: Creseis acicula | S1: Creseis acicula (transparent) | T1: Clio cuspidata | U1: Clio cuspidata (transparent) | V1: Clio pyramidata | W1: Clio pyramidata (transparent) | X1: Cavolinia sp. | Y1: Cavolinia sp. (transparent) | Z1: Clionidarum | AA1: Total
A2: 9-105 | B2: 101 | C2: 10.298053 | D2: 0 | E2: 0 | F2: 0 | G2: 0 | H2: 0 | I2: 0 | J2: 0 | K2: 0 | L2: 0 | M2: 0 | N2: 0 | O2: 0 | P2: 0 | Q2: 0 | R2: 0 | S2: 0 | T2: 0 | U2: 0 | V2: 0 | W2: 0 | X2: 0 | Y2: 0 | Z2: 0 | AA2: =SUM(D2:Z2) -> 0
A3: 9-015 | B3: 191 | C3: 11.768078 | D3: 0 | E3: 0 | F3: 0 | G3: 0 | H3: 0 | I3: 0 | J3: 0 | K3: 0 | L3: 0 | M3: 0 | N3: 0 | O3: 0 | P3: 0 | Q3: 0 | R3: 0 | S3: 0 | T3: 0 | U3: 0 | V3: 0 | W3: 0 | X3: 0 | Y3: 0 | Z3: 0 | AA3: =SUM(D3:Z3) -> 0
A4: 8-145 | B4: 211 | C4: 12.140505 | D4: 0 | E4: 0 | F4: 0 | G4: 0 | H4: 0 | I4: 0 | J4: 0 | K4: 0 | L4: 0 | M4: 0 | N4: 0 | O4: 0 | P4: 0 | Q4: 0 | R4: 0 | S4: 0 | T4: 0 | U4: 0 | V4: 0 | W4: 0 | X4: 0 | Y4: 0 | Z4: 0 | AA4: =SUM(D4:Z4) -> 0
A5: 8-075 | B5: 281 | C5: 12.681927 | D5: 3 | E5: 1 | F5: 7 | G5: 1 | H5: 2 | I5: 0 | J5: 0 | K5: 0 | L5: 0 | M5: 0 | N5: 0 | O5: 0 | P5: 0 | Q5: 2 | R5: 0 | S5: 0 | T5: 0 | U5: 0 | V5: 1 | W5: 0 | X5: 0 | Y5: 0 | Z5: 0 | AA5: =SUM(D5:Z5) -> 17
A6: 8-020 | B6: 336 | C6: 12.90434 | D6: 20 | E6: 1 | F6: 31 | G6: 10 | H6: 2 | I6: 0 | J6: 0 | K6: 3 | L6: 0 | M6: 1 | N6: 0 | O6: 0 | P6: 5 | Q6: 2 | R6: 1 | S6: 0 | T6: 2 | U6: 0 | V6: 1 | W6: 0 | X6: 0 | Y6: 0 | Z6: 0 | AA6: =SUM(D6:Z6) -> 79
A7: 7-025 | B7: 482 | C7: 13.4115 | D7: 5 | E7: 0 | F7: 6 | G7: 1 | H7: 1 | I7: 0 | J7: 0 | K7: 0 | L7: 0 | M7: 0 | N7: 0 | O7: 0 | P7: 3 | Q7: 0 | R7: 0 | S7: 0 | T7: 0 | U7: 0 | V7: 0 | W7: 0 | X7: 2 | Y7: 0 | Z7: 0 | AA7: =SUM(D7:Z7) -> 18
A8: 6a-075 | B8: 542 | C8: 15.297745 | D8: 29 | E8: 20 | F8: 6 | G8: 4 | H8: 8 | I8: 3 | J8: 0 | K8: 0 | L8: 0 | M8: 1 | N8: 1 | O8: 0 | P8: 1 | Q8: 4 | R8: 1 | S8: 0 | T8: 0 | U8: 0 | V8: 0 | W8: 0 | X8: 0 | Y8: 0 | Z8: 1 | AA8: =SUM(D8:Z8) -> 79
A9: 6a-010 | B9: 607 | C9: 17.630333 | D9: 3 | E9: 1 | F9: 2 | G9: 0 | H9: 0 | I9: 0 | J9: 0 | K9: 0 | L9: 0 | M9: 0 | N9: 0 | O9: 0 | P9: 0 | Q9: 0 | R9: 1 | S9: 0 | T9: 0 | U9: 0 | V9: 0 | W9: 0 | X9: 1 | Y9: 0 | Z9: 0 | AA9: =SUM(D9:Z9) -> 8
A10: 6-125 | B10: 641 | C10: 19.789979 | D10: 9 | E10: 0 | F10: 6 | G10: 0 | H10: 1 | I10: 0 | J10: 0 | K10: 0 | L10: 0 | M10: 0 | N10: 2 | O10: 1 | P10: 5 | Q10: 7 | R10: 0 | S10: 0 | T10: 0 | U10: 0 | V10: 1 | W10: 0 | X10: 2 | Y10: 0 | Z10: 0 | AA10: =SUM(D10:Z10) -> 34
A11: 6-090 | B11: 676 | C11: 22.102144 | D11: 15 | E11: 1 | F11: 1 | G11: 0 | H11: 4 | I11: 1 | J11: 0 | K11: 0 | L11: 0 | M11: 0 | N11: 0 | O11: 0 | P11: 3 | Q11: 1 | R11: 0 | S11: 0 | T11: 0 | U11: 1 | V11: 1 | W11: 0 | X11: 2 | Y11: 1 | Z11: 0 | AA11: =SUM(D11:Z11) -> 31
A12: 6-020 | B12: 746 | C12: 26.142462 | D12: 60 | E12: 29 | F12: 10 | G12: 11 | H12: 8 | I12: 2 | J12: 2 | K12: 1 | L12: 0 | M12: 1 | N12: 2 | O12: 2 | P12: 13 | Q12: 6 | R12: 1 | S12: 1 | T12: 1 | U12: 1 | V12: 4 | W12: 0 | X12: 3 | Y12: 1 | Z12: 0 | AA12: =SUM(D12:Z12) -> 159
A13: 4-060 | B13: 833 | C13: 29.476255 | D13: 0 | E13: 0 | F13: 0 | G13: 0 | H13: 0 | I13: 0 | J13: 0 | K13: 0 | L13: 0 | M13: 0 | N13: 0 | O13: 0 | P13: 1 | Q13: 0 | R13: 0 | S13: 0 | T13: 0 | U13: 0 | V13: 0 | W13: 0 | X13: 0 | Y13: 0 | Z13: 0 | AA13: =SUM(D13:Z13) -> 1
... A16: 2-025 | B16: 1021 | C16: 33.121 | D16: 0 | E16: 0 | F16: 0 | G16: 0 | H16: 0 | I16: 0 | J16: 0 | K16: 0 | L16: 0 | M16: 0 | N16: 0 | O16: 0 | P16: 0 | Q16: 0 | R16: 0 | S16: 0 | T16: 0 | U16: 0 | V16: 0 | W16: 0 | X16: 0 | Y16: 0 | Z16: 0 | AA16: =SUM(D16:Z16) -> 0

Sheet Species
A1: Sample | B1: cmbs | C1: Age R396 x 1000 | D1: Heliconoides inflatus | E1: Heliconoides inflatus (transparent) | F1: Limacina trochiformis | G1: Limacina trochiformis (transparent) | H1: Limacina retroversa | I1: Limacina retroversa (transparent) | J1: Limacina retroversa (striata) | K1: Limacina bulimoides | L1: Limacina bulimoides (transparent) | M1: Limacina bulimoides (striata) | N1: Creseis sp. | O1: Creseis sp. (transparent) | P1: Creseis conica | Q1: Creseis conica (transparent) | R1: Creseis acicula | S1: Creseis acicula (transparent) | T1: Clio cuspidata | U1: Clio cuspidata (transparent) | V1: Clio pyramidata | W1: Clio pyramidata (transparent) | X1: Cavolinia sp. | Y1: Cavolinia sp. (transparent) | Z1: Clionidarum | AA1: Total | AC1: Total Heliconoides inflatus | AD1: Total Limacina trochiformis | AE1: Total Limacina retroversa | AF1: Total Limacina bulimoides | AG1: Total Creseis sp. | AH1: Total Creseis conica | AI1: Total Creseis acicula | AJ1: Total Clio cuspidata | AK1: Total Clio pyramidata | AL1: Total Cavolinia sp. | AM1: Total Clionidarum | AN1: Transparent ratio
A2: 9-105 | B2: 101 | C2: 10.298053 | D2: =SUM('250-600 μm'!D2+'150-250 μm '!D2+'150-600 μm (rest)'!D2) -> 1 | E2: =SUM('250-600 μm'!E2+'150-250 μm '!E2+'150-600 μm (rest)'!E2) -> 0 | F2: =SUM('250-600 μm'!F2+'150-250 μm '!F2+'150-600 μm (rest)'!F2) -> 1 | G2: =SUM('250-600 μm'!G2+'150-250 μm '!G2+'150-600 μm (rest)'!G2) -> 0 | H2: =SUM('250-600 μm'!H2+'150-250 μm '!H2+'150-600 μm (rest)'!H2) -> 0 | I2: =SUM('250-600 μm'!I2+'150-250 μm '!I2+'150-600 μm (rest)'!I2) -> 0 | J2: =SUM('250-600 μm'!J2+'150-250 μm '!J2+'150-600 μm (rest)'!J2) -> 0 | K2: =SUM('250-600 μm'!K2+'150-250 μm '!K2+'150-600 μm (rest)'!K2) -> 0 | ... Z2: =SUM('250-600 μm'!Z2+'150-250 μm '!Z2+'150-600 μm (rest)'!Z2) -> 0 | AA2: =SUM(D2:Z2) -> 4 | AC2: =SUM(D2:E2) -> 1 | AD2: =SUM(F2:G2) -> 1 | AE2: =SUM(H2:J2) -> 0 | AF2: =SUM(K2:M2) -> 0 | AG2: =SUM(N2:O2) -> 0 | AH2: =SUM(P2:Q2) -> 0 | AI2: =SUM(R2:S2) -> 0 | AJ2: =SUM(T2:U2) -> 1 | AK2: =SUM(V2:W2) -> 0 | AL2: =SUM(X2:Y2) -> 1 | AM2: =Z2 -> 0 | AN2: =(E2+G2+I2+L2+O2+Q2+S2+U2+W2+Y2)/(AA2) -> 0
A3: 9-015 | B3: 191 | C3: 11.768078 | D3: =SUM('250-600 μm'!D3+'150-250 μm '!D3+'150-600 μm (rest)'!D3) -> 18 | E3: =SUM('250-600 μm'!E3+'150-250 μm '!E3+'150-600 μm (rest)'!E3) -> 9 | F3: =SUM('250-600 μm'!F3+'150-250 μm '!F3+'150-600 μm (rest)'!F3) -> 34 | G3: =SUM('250-600 μm'!G3+'150-250 μm '!G3+'150-600 μm (rest)'!G3) -> 6 | H3: =SUM('250-600 μm'!H3+'150-250 μm '!H3+'150-600 μm (rest)'!H3) -> 2 | I3: =SUM('250-600 μm'!I3+'150-250 μm '!I3+'150-600 μm (rest)'!I3) -> 0 | J3: =SUM('250-600 μm'!J3+'150-250 μm '!J3+'150-600 μm (rest)'!J3) -> 0 | K3: =SUM('250-600 μm'!K3+'150-250 μm '!K3+'150-600 μm (rest)'!K3) -> 0 | ... Z3: =SUM('250-600 μm'!Z3+'150-250 μm '!Z3+'150-600 μm (rest)'!Z3) -> 0 | AA3: =SUM(D3:Z3) -> 73 | AC3: =SUM(D3:E3) -> 27 | AD3: =SUM(F3:G3) -> 40 | AE3: =SUM(H3:J3) -> 2 | AF3: =SUM(K3:M3) -> 0 | AG3: =SUM(N3:O3) -> 0 | AH3: =SUM(P3:Q3) -> 3 | AI3: =SUM(R3:S3) -> 0 | AJ3: =SUM(T3:U3) -> 0 | AK3: =SUM(V3:W3) -> 0 | AL3: =SUM(X3:Y3) -> 1 | AM3: =Z3 -> 0 | AN3: =(E3+G3+I3+L3+O3+Q3+S3+U3+W3+Y3)/(AA3) -> 0.20547945
A4: 8-145 | B4: 211 | C4: 12.140505 | D4: =SUM('250-600 μm'!D4+'150-250 μm '!D4+'150-600 μm (rest)'!D4) -> 8 | E4: =SUM('250-600 μm'!E4+'150-250 μm '!E4+'150-600 μm (rest)'!E4) -> 0 | F4: =SUM('250-600 μm'!F4+'150-250 μm '!F4+'150-600 μm (rest)'!F4) -> 36 | G4: =SUM('250-600 μm'!G4+'150-250 μm '!G4+'150-600 μm (rest)'!G4) -> 2 | H4: =SUM('250-600 μm'!H4+'150-250 μm '!H4+'150-600 μm (rest)'!H4) -> 4 | I4: =SUM('250-600 μm'!I4+'150-250 μm '!I4+'150-600 μm (rest)'!I4) -> 0 | J4: =SUM('250-600 μm'!J4+'150-250 μm '!J4+'150-600 μm (rest)'!J4) -> 0 | K4: =SUM('250-600 μm'!K4+'150-250 μm '!K4+'150-600 μm (rest)'!K4) -> 0 | ... Z4: =SUM('250-600 μm'!Z4+'150-250 μm '!Z4+'150-600 μm (rest)'!Z4) -> 0 | AA4: =SUM(D4:Z4) -> 59 | AC4: =SUM(D4:E4) -> 8 | AD4: =SUM(F4:G4) -> 38 | AE4: =SUM(H4:J4) -> 4 | AF4: =SUM(K4:M4) -> 0 | AG4: =SUM(N4:O4) -> 0 | AH4: =SUM(P4:Q4) -> 1 | AI4: =SUM(R4:S4) -> 3 | AJ4: =SUM(T4:U4) -> 1 | AK4: =SUM(V4:W4) -> 0 | AL4: =SUM(X4:Y4) -> 4 | AM4: =Z4 -> 0 | AN4: =(E4+G4+I4+L4+O4+Q4+S4+U4+W4+Y4)/(AA4) -> 0.06779661
A5: 8-075 | B5: 281 | C5: 12.681927 | D5: =SUM('250-600 μm'!D5+'150-250 μm '!D5+'150-600 μm (rest)'!D5) -> 5 | E5: =SUM('250-600 μm'!E5+'150-250 μm '!E5+'150-600 μm (rest)'!E5) -> 1 | F5: =SUM('250-600 μm'!F5+'150-250 μm '!F5+'150-600 μm (rest)'!F5) -> 13 | G5: =SUM('250-600 μm'!G5+'150-250 μm '!G5+'150-600 μm (rest)'!G5) -> 1 | H5: =SUM('250-600 μm'!H5+'150-250 μm '!H5+'150-600 μm (rest)'!H5) -> 2 | I5: =SUM('250-600 μm'!I5+'150-250 μm '!I5+'150-600 μm (rest)'!I5) -> 0 | J5: =SUM('250-600 μm'!J5+'150-250 μm '!J5+'150-600 μm (rest)'!J5) -> 1 | K5: =SUM('250-600 μm'!K5+'150-250 μm '!K5+'150-600 μm (rest)'!K5) -> 0 | ... Z5: =SUM('250-600 μm'!Z5+'150-250 μm '!Z5+'150-600 μm (rest)'!Z5) -> 0 | AA5: =SUM(D5:Z5) -> 29 | AC5: =SUM(D5:E5) -> 6 | AD5: =SUM(F5:G5) -> 14 | AE5: =SUM(H5:J5) -> 3 | AF5: =SUM(K5:M5) -> 0 | AG5: =SUM(N5:O5) -> 0 | AH5: =SUM(P5:Q5) -> 3 | AI5: =SUM(R5:S5) -> 0 | AJ5: =SUM(T5:U5) -> 1 | AK5: =SUM(V5:W5) -> 1 | AL5: =SUM(X5:Y5) -> 1 | AM5: =Z5 -> 0 | AN5: =(E5+G5+I5+L5+O5+Q5+S5+U5+W5+Y5)/(AA5) -> 0.13793103
A6: 8-020 | B6: 336 | C6: 12.90434 | D6: =SUM('250-600 μm'!D6+'150-250 μm '!D6+'150-600 μm (rest)'!D6) -> 22 | E6: =SUM('250-600 μm'!E6+'150-250 μm '!E6+'150-600 μm (rest)'!E6) -> 2 | F6: =SUM('250-600 μm'!F6+'150-250 μm '!F6+'150-600 μm (rest)'!F6) -> 45 | G6: =SUM('250-600 μm'!G6+'150-250 μm '!G6+'150-600 μm (rest)'!G6) -> 22 | H6: =SUM('250-600 μm'!H6+'150-250 μm '!H6+'150-600 μm (rest)'!H6) -> 2 | I6: =SUM('250-600 μm'!I6+'150-250 μm '!I6+'150-600 μm (rest)'!I6) -> 0 | J6: =SUM('250-600 μm'!J6+'150-250 μm '!J6+'150-600 μm (rest)'!J6) -> 0 | K6: =SUM('250-600 μm'!K6+'150-250 μm '!K6+'150-600 μm (rest)'!K6) -> 3 | ... Z6: =SUM('250-600 μm'!Z6+'150-250 μm '!Z6+'150-600 μm (rest)'!Z6) -> 0 | AA6: =SUM(D6:Z6) -> 118 | AC6: =SUM(D6:E6) -> 24 | AD6: =SUM(F6:G6) -> 67 | AE6: =SUM(H6:J6) -> 2 | AF6: =SUM(K6:M6) -> 4 | AG6: =SUM(N6:O6) -> 0 | AH6: =SUM(P6:Q6) -> 14 | AI6: =SUM(R6:S6) -> 2 | AJ6: =SUM(T6:U6) -> 3 | AK6: =SUM(V6:W6) -> 1 | AL6: =SUM(X6:Y6) -> 1 | AM6: =Z6 -> 0 | AN6: =(E6+G6+I6+L6+O6+Q6+S6+U6+W6+Y6)/(AA6) -> 0.24576271
A7: 7-025 | B7: 482 | C7: 13.4115 | D7: =SUM('250-600 μm'!D7+'150-250 μm '!D7+'150-600 μm (rest)'!D7) -> 5 | E7: =SUM('250-600 μm'!E7+'150-250 μm '!E7+'150-600 μm (rest)'!E7) -> 0 | F7: =SUM('250-600 μm'!F7+'150-250 μm '!F7+'150-600 μm (rest)'!F7) -> 6 | G7: =SUM('250-600 μm'!G7+'150-250 μm '!G7+'150-600 μm (rest)'!G7) -> 1 | H7: =SUM('250-600 μm'!H7+'150-250 μm '!H7+'150-600 μm (rest)'!H7) -> 1 | I7: =SUM('250-600 μm'!I7+'150-250 μm '!I7+'150-600 μm (rest)'!I7) -> 0 | J7: =SUM('250-600 μm'!J7+'150-250 μm '!J7+'150-600 μm (rest)'!J7) -> 0 | K7: =SUM('250-600 μm'!K7+'150-250 μm '!K7+'150-600 μm (rest)'!K7) -> 0 | ... Z7: =SUM('250-600 μm'!Z7+'150-250 μm '!Z7+'150-600 μm (rest)'!Z7) -> 0 | AA7: =SUM(D7:Z7) -> 18 | AC7: =SUM(D7:E7) -> 5 | AD7: =SUM(F7:G7) -> 7 | AE7: =SUM(H7:J7) -> 1 | AF7: =SUM(K7:M7) -> 0 | AG7: =SUM(N7:O7) -> 0 | AH7: =SUM(P7:Q7) -> 3 | AI7: =SUM(R7:S7) -> 0 | AJ7: =SUM(T7:U7) -> 0 | AK7: =SUM(V7:W7) -> 0 | AL7: =SUM(X7:Y7) -> 2 | AM7: =Z7 -> 0 | AN7: =(E7+G7+I7+L7+O7+Q7+S7+U7+W7+Y7)/(AA7) -> 0.055555556
A8: 6a-075 | B8: 542 | C8: 15.297745 | D8: =SUM('250-600 μm'!D8+'150-250 μm '!D8+'150-600 μm (rest)'!D8) -> 66 | E8: =SUM('250-600 μm'!E8+'150-250 μm '!E8+'150-600 μm (rest)'!E8) -> 34 | F8: =SUM('250-600 μm'!F8+'150-250 μm '!F8+'150-600 μm (rest)'!F8) -> 15 | G8: =SUM('250-600 μm'!G8+'150-250 μm '!G8+'150-600 μm (rest)'!G8) -> 5 | H8: =SUM('250-600 μm'!H8+'150-250 μm '!H8+'150-600 μm (rest)'!H8) -> 9 | I8: =SUM('250-600 μm'!I8+'150-250 μm '!I8+'150-600 μm (rest)'!I8) -> 3 | J8: =SUM('250-600 μm'!J8+'150-250 μm '!J8+'150-600 μm (rest)'!J8) -> 0 | K8: =SUM('250-600 μm'!K8+'150-250 μm '!K8+'150-600 μm (rest)'!K8) -> 0 | ... Z8: =SUM('250-600 μm'!Z8+'150-250 μm '!Z8+'150-600 μm (rest)'!Z8) -> 1 | AA8: =SUM(D8:Z8) -> 149 | AC8: =SUM(D8:E8) -> 100 | AD8: =SUM(F8:G8) -> 20 | AE8: =SUM(H8:J8) -> 12 | AF8: =SUM(K8:M8) -> 1 | AG8: =SUM(N8:O8) -> 1 | AH8: =SUM(P8:Q8) -> 10 | AI8: =SUM(R8:S8) -> 1 | AJ8: =SUM(T8:U8) -> 0 | AK8: =SUM(V8:W8) -> 0 | AL8: =SUM(X8:Y8) -> 3 | AM8: =Z8 -> 1 | AN8: =(E8+G8+I8+L8+O8+Q8+S8+U8+W8+Y8)/(AA8) -> 0.32214765
A9: 6a-010 | B9: 607 | C9: 17.630333 | D9: =SUM('250-600 μm'!D9+'150-250 μm '!D9+'150-600 μm (rest)'!D9) -> 8 | E9: =SUM('250-600 μm'!E9+'150-250 μm '!E9+'150-600 μm (rest)'!E9) -> 1 | F9: =SUM('250-600 μm'!F9+'150-250 μm '!F9+'150-600 μm (rest)'!F9) -> 5 | G9: =SUM('250-600 μm'!G9+'150-250 μm '!G9+'150-600 μm (rest)'!G9) -> 0 | H9: =SUM('250-600 μm'!H9+'150-250 μm '!H9+'150-600 μm (rest)'!H9) -> 0 | I9: =SUM('250-600 μm'!I9+'150-250 μm '!I9+'150-600 μm (rest)'!I9) -> 0 | J9: =SUM('250-600 μm'!J9+'150-250 μm '!J9+'150-600 μm (rest)'!J9) -> 0 | K9: =SUM('250-600 μm'!K9+'150-250 μm '!K9+'150-600 μm (rest)'!K9) -> 0 | ... Z9: =SUM('250-600 μm'!Z9+'150-250 μm '!Z9+'150-600 μm (rest)'!Z9) -> 0 | AA9: =SUM(D9:Z9) -> 16 | AC9: =SUM(D9:E9) -> 9 | AD9: =SUM(F9:G9) -> 5 | AE9: =SUM(H9:J9) -> 0 | AF9: =SUM(K9:M9) -> 0 | AG9: =SUM(N9:O9) -> 0 | AH9: =SUM(P9:Q9) -> 0 | AI9: =SUM(R9:S9) -> 1 | AJ9: =SUM(T9:U9) -> 0 | AK9: =SUM(V9:W9) -> 0 | AL9: =SUM(X9:Y9) -> 1 | AM9: =Z9 -> 0 | AN9: =(E9+G9+I9+L9+O9+Q9+S9+U9+W9+Y9)/(AA9) -> 0.0625
A10: 6-125 | B10: 641 | C10: 19.789979 | D10: =SUM('250-600 μm'!D10+'150-250 μm '!D10+'150-600 μm (rest)'!D10) -> 9 | E10: =SUM('250-600 μm'!E10+'150-250 μm '!E10+'150-600 μm (rest)'!E10) -> 0 | F10: =SUM('250-600 μm'!F10+'150-250 μm '!F10+'150-600 μm (rest)'!F10) -> 6 | G10: =SUM('250-600 μm'!G10+'150-250 μm '!G10+'150-600 μm (rest)'!G10) -> 0 | H10: =SUM('250-600 μm'!H10+'150-250 μm '!H10+'150-600 μm (rest)'!H10) -> 1 | I10: =SUM('250-600 μm'!I10+'150-250 μm '!I10+'150-600 μm (rest)'!I10) -> 0 | J10: =SUM('250-600 μm'!J10+'150-250 μm '!J10+'150-600 μm (rest)'!J10) -> 0 | K10: =SUM('250-600 μm'!K10+'150-250 μm '!K10+'150-600 μm (rest)'!K10) -> 0 | ... Z10: =SUM('250-600 μm'!Z10+'150-250 μm '!Z10+'150-600 μm (rest)'!Z10) -> 0 | AA10: =SUM(D10:Z10) -> 34 | AC10: =SUM(D10:E10) -> 9 | AD10: =SUM(F10:G10) -> 6 | AE10: =SUM(H10:J10) -> 1 | AF10: =SUM(K10:M10) -> 0 | AG10: =SUM(N10:O10) -> 3 | AH10: =SUM(P10:Q10) -> 12 | AI10: =SUM(R10:S10) -> 0 | AJ10: =SUM(T10:U10) -> 0 | AK10: =SUM(V10:W10) -> 1 | AL10: =SUM(X10:Y10) -> 2 | AM10: =Z10 -> 0 | AN10: =(E10+G10+I10+L10+O10+Q10+S10+U10+W10+Y10)/(AA10) -> 0.23529412
A11: 6-090 | B11: 676 | C11: 22.102144 | D11: =SUM('250-600 μm'!D11+'150-250 μm '!D11+'150-600 μm (rest)'!D11) -> 15 | E11: =SUM('250-600 μm'!E11+'150-250 μm '!E11+'150-600 μm (rest)'!E11) -> 1 | F11: =SUM('250-600 μm'!F11+'150-250 μm '!F11+'150-600 μm (rest)'!F11) -> 1 | G11: =SUM('250-600 μm'!G11+'150-250 μm '!G11+'150-600 μm (rest)'!G11) -> 0 | H11: =SUM('250-600 μm'!H11+'150-250 μm '!H11+'150-600 μm (rest)'!H11) -> 4 | I11: =SUM('250-600 μm'!I11+'150-250 μm '!I11+'150-600 μm (rest)'!I11) -> 1 | J11: =SUM('250-600 μm'!J11+'150-250 μm '!J11+'150-600 μm (rest)'!J11) -> 0 | K11: =SUM('250-600 μm'!K11+'150-250 μm '!K11+'150-600 μm (rest)'!K11) -> 0 | ... Z11: =SUM('250-600 μm'!Z11+'150-250 μm '!Z11+'150-600 μm (rest)'!Z11) -> 0 | AA11: =SUM(D11:Z11) -> 31 | AC11: =SUM(D11:E11) -> 16 | AD11: =SUM(F11:G11) -> 1 | AE11: =SUM(H11:J11) -> 5 | AF11: =SUM(K11:M11) -> 0 | AG11: =SUM(N11:O11) -> 0 | AH11: =SUM(P11:Q11) -> 4 | AI11: =SUM(R11:S11) -> 0 | AJ11: =SUM(T11:U11) -> 1 | AK11: =SUM(V11:W11) -> 1 | AL11: =SUM(X11:Y11) -> 3 | AM11: =Z11 -> 0 | AN11: =(E11+G11+I11+L11+O11+Q11+S11+U11+W11+Y11)/(AA11) -> 0.16129032
A12: 6-020 | B12: 746 | C12: 26.142462 | D12: =SUM('250-600 μm'!D12+'150-250 μm '!D12+'150-600 μm (rest)'!D12) -> 65 | E12: =SUM('250-600 μm'!E12+'150-250 μm '!E12+'150-600 μm (rest)'!E12) -> 29 | F12: =SUM('250-600 μm'!F12+'150-250 μm '!F12+'150-600 μm (rest)'!F12) -> 11 | G12: =SUM('250-600 μm'!G12+'150-250 μm '!G12+'150-600 μm (rest)'!G12) -> 11 | H12: =SUM('250-600 μm'!H12+'150-250 μm '!H12+'150-600 μm (rest)'!H12) -> 8 | I12: =SUM('250-600 μm'!I12+'150-250 μm '!I12+'150-600 μm (rest)'!I12) -> 2 | J12: =SUM('250-600 μm'!J12+'150-250 μm '!J12+'150-600 μm (rest)'!J12) -> 2 | K12: =SUM('250-600 μm'!K12+'150-250 μm '!K12+'150-600 μm (rest)'!K12) -> 1 | ... Z12: =SUM('250-600 μm'!Z12+'150-250 μm '!Z12+'150-600 μm (rest)'!Z12) -> 0 | AA12: =SUM(D12:Z12) -> 167 | AC12: =SUM(D12:E12) -> 94 | AD12: =SUM(F12:G12) -> 22 | AE12: =SUM(H12:J12) -> 12 | AF12: =SUM(K12:M12) -> 2 | AG12: =SUM(N12:O12) -> 4 | AH12: =SUM(P12:Q12) -> 20 | AI12: =SUM(R12:S12) -> 2 | AJ12: =SUM(T12:U12) -> 2 | AK12: =SUM(V12:W12) -> 4 | AL12: =SUM(X12:Y12) -> 5 | AM12: =Z12 -> 0 | AN12: =(E12+G12+I12+L12+O12+Q12+S12+U12+W12+Y12)/(AA12) -> 0.31736527
A13: 4-060 | B13: 833 | C13: 29.476255 | D13: =SUM('250-600 μm'!D13+'150-250 μm '!D13+'150-600 μm (rest)'!D13) -> 0 | E13: =SUM('250-600 μm'!E13+'150-250 μm '!E13+'150-600 μm (rest)'!E13) -> 0 | F13: =SUM('250-600 μm'!F13+'150-250 μm '!F13+'150-600 μm (rest)'!F13) -> 1 | G13: =SUM('250-600 μm'!G13+'150-250 μm '!G13+'150-600 μm (rest)'!G13) -> 0 | H13: =SUM('250-600 μm'!H13+'150-250 μm '!H13+'150-600 μm (rest)'!H13) -> 0 | I13: =SUM('250-600 μm'!I13+'150-250 μm '!I13+'150-600 μm (rest)'!I13) -> 0 | J13: =SUM('250-600 μm'!J13+'150-250 μm '!J13+'150-600 μm (rest)'!J13) -> 0 | K13: =SUM('250-600 μm'!K13+'150-250 μm '!K13+'150-600 μm (rest)'!K13) -> 0 | ... Z13: =SUM('250-600 μm'!Z13+'150-250 μm '!Z13+'150-600 μm (rest)'!Z13) -> 0 | AA13: =SUM(D13:Z13) -> 2 | AC13: =SUM(D13:E13) -> 0 | AD13: =SUM(F13:G13) -> 1 | AE13: =SUM(H13:J13) -> 0 | AF13: =SUM(K13:M13) -> 0 | AG13: =SUM(N13:O13) -> 0 | AH13: =SUM(P13:Q13) -> 1 | AI13: =SUM(R13:S13) -> 0 | AJ13: =SUM(T13:U13) -> 0 | AK13: =SUM(V13:W13) -> 0 | AL13: =SUM(X13:Y13) -> 0 | AM13: =Z13 -> 0 | AN13: =(E13+G13+I13+L13+O13+Q13+S13+U13+W13+Y13)/(AA13) -> 0
A14: 4-005 | B14: 888 | C14: 30.863619 | D14: =SUM('250-600 μm'!D14+'150-250 μm '!D14+'150-600 μm (rest)'!D14) -> 1 | E14: =SUM('250-600 μm'!E14+'150-250 μm '!E14+'150-600 μm (rest)'!E14) -> 0 | F14: =SUM('250-600 μm'!F14+'150-250 μm '!F14+'150-600 μm (rest)'!F14) -> 0 | G14: =SUM('250-600 μm'!G14+'150-250 μm '!G14+'150-600 μm (rest)'!G14) -> 0 | H14: =SUM('250-600 μm'!H14+'150-250 μm '!H14+'150-600 μm (rest)'!H14) -> 0 | I14: =SUM('250-600 μm'!I14+'150-250 μm '!I14+'150-600 μm (rest)'!I14) -> 0 | J14: =SUM('250-600 μm'!J14+'150-250 μm '!J14+'150-600 μm (rest)'!J14) -> 0 | K14: =SUM('250-600 μm'!K14+'150-250 μm '!K14+'150-600 μm (rest)'!K14) -> 0 | ... Z14: =SUM('250-600 μm'!Z14+'150-250 μm '!Z14+'150-600 μm (rest)'!Z14) -> 0 | AA14: =SUM(D14:Z14) -> 3 | AC14: =SUM(D14:E14) -> 1 | AD14: =SUM(F14:G14) -> 0 | AE14: =SUM(H14:J14) -> 0 | AF14: =SUM(K14:M14) -> 0 | AG14: =SUM(N14:O14) -> 2 | AH14: =SUM(P14:Q14) -> 0 | AI14: =SUM(R14:S14) -> 0 | AJ14: =SUM(T14:U14) -> 0 | AK14: =SUM(V14:W14) -> 0 | AL14: =SUM(X14:Y14) -> 0 | AM14: =Z14 -> 0 | AN14: =(E14+G14+I14+L14+O14+Q14+S14+U14+W14+Y14)/(AA14) -> 0
A15: 3-031 | B15: 940 | C15: 31.496038 | D15: =SUM('250-600 μm'!D15+'150-250 μm '!D15+'150-600 μm (rest)'!D15) -> 0 | E15: =SUM('250-600 μm'!E15+'150-250 μm '!E15+'150-600 μm (rest)'!E15) -> 0 | F15: =SUM('250-600 μm'!F15+'150-250 μm '!F15+'150-600 μm (rest)'!F15) -> 0 | G15: =SUM('250-600 μm'!G15+'150-250 μm '!G15+'150-600 μm (rest)'!G15) -> 0 | H15: =SUM('250-600 μm'!H15+'150-250 μm '!H15+'150-600 μm (rest)'!H15) -> 0 | I15: =SUM('250-600 μm'!I15+'150-250 μm '!I15+'150-600 μm (rest)'!I15) -> 0 | J15: =SUM('250-600 μm'!J15+'150-250 μm '!J15+'150-600 μm (rest)'!J15) -> 0 | K15: =SUM('250-600 μm'!K15+'150-250 μm '!K15+'150-600 μm (rest)'!K15) -> 0 | ... Z15: =SUM('250-600 μm'!Z15+'150-250 μm '!Z15+'150-600 μm (rest)'!Z15) -> 0 | AA15: =SUM(D15:Z15) -> 0 | AC15: =SUM(D15:E15) -> 0 | AD15: =SUM(F15:G15) -> 0 | AE15: =SUM(H15:J15) -> 0 | AF15: =SUM(K15:M15) -> 0 | AG15: =SUM(N15:O15) -> 0 | AH15: =SUM(P15:Q15) -> 0 | AI15: =SUM(R15:S15) -> 0 | AJ15: =SUM(T15:U15) -> 0 | AK15: =SUM(V15:W15) -> 0 | AL15: =SUM(X15:Y15) -> 0 | AM15: =Z15 -> 0 | AN15: 0
A16: 2-025 | B16: 1021 | C16: 33.121 | D16: =SUM('250-600 μm'!D16+'150-250 μm '!D16+'150-600 μm (rest)'!D16) -> 0 | E16: =SUM('250-600 μm'!E16+'150-250 μm '!E16+'150-600 μm (rest)'!E16) -> 0 | F16: =SUM('250-600 μm'!F16+'150-250 μm '!F16+'150-600 μm (rest)'!F16) -> 0 | G16: =SUM('250-600 μm'!G16+'150-250 μm '!G16+'150-600 μm (rest)'!G16) -> 0 | H16: =SUM('250-600 μm'!H16+'150-250 μm '!H16+'150-600 μm (rest)'!H16) -> 0 | I16: =SUM('250-600 μm'!I16+'150-250 μm '!I16+'150-600 μm (rest)'!I16) -> 0 | J16: =SUM('250-600 μm'!J16+'150-250 μm '!J16+'150-600 μm (rest)'!J16) -> 0 | K16: =SUM('250-600 μm'!K16+'150-250 μm '!K16+'150-600 μm (rest)'!K16) -> 0 | ... Z16: =SUM('250-600 μm'!Z16+'150-250 μm '!Z16+'150-600 μm (rest)'!Z16) -> 0 | AA16: =SUM(D16:Z16) -> 0 | AC16: =SUM(D16:E16) -> 0 | AD16: =SUM(F16:G16) -> 0 | AE16: =SUM(H16:J16) -> 0 | AF16: =SUM(K16:M16) -> 0 | AG16: =SUM(N16:O16) -> 0 | AH16: =SUM(P16:Q16) -> 0 | AI16: =SUM(R16:S16) -> 0 | AJ16: =SUM(T16:U16) -> 0 | AK16: =SUM(V16:W16) -> 0 | AL16: =SUM(X16:Y16) -> 0 | AM16: =Z16 -> 0 | AN16: 0
A17: Total | D17: =SUM(D2:D16) -> 223 | E17: =SUM(E2:E16) -> 77 | F17: =SUM(F2:F16) -> 174 | G17: =SUM(G2:G16) -> 48 | H17: =SUM(H2:H16) -> 33 | I17: =SUM(I2:I16) -> 6 | J17: =SUM(J2:J16) -> 3 | K17: =SUM(K2:K16) -> 4 | ... AA17: =SUM(AA2:AA16) -> 703 | AC17: =SUM(D17:E17) -> 300 | AD17: =SUM(F17:G17) -> 222 | AE17: =SUM(H17:J17) -> 42 | AF17: =SUM(K17:M17) -> 7 | AG17: =SUM(N17:O17) -> 10 | AH17: =SUM(P17:Q17) -> 71 | AI17: =SUM(R17:S17) -> 9 | AJ17: =SUM(T17:U17) -> 9 | AK17: =SUM(V17:W17) -> 8 | AL17: =SUM(X17:Y17) -> 24 | AM17: =Z17 -> 1 | AN17: =(E17+G17+I17+L17+O17+Q17+S17+U17+W17+Y17)/(AA17) -> 0.23897582
A18: Transparent ratio | E18: =E17/(D17+E17) -> 0.25666667 | G18: =G17/(F17+G17) -> 0.21621622 | J18: =I17/(H17+I17+J17) -> 0.14285714 | M18: =L17/(K17+L17+M17) -> 0 | O18: =O17/(N17+O17) -> 0.3 | Q18: =Q17/(P17+Q17) -> 0.38028169 | S18: =S17/(R17+S17) -> 0.33333333 | U18: =U17/(T17+U17) -> 0.22222222 | W18: =W17/(V17+W17) -> 0 | Y18: =Y17/(X17+Y17) -> 0.083333333 | Z18: 0

Sheet Species percentage
A1: Sample | B1: cmbs | C1: Age R396 x 1000 | D1: Total Heliconoides inflatus | E1: Total Heliconoides inflatus | F1: Total Heliconoides inflatus | G1: Total Limacina bulimoides | H1: Total Creseis sp. | I1: Total Creseis conica | J1: Total Creseis acicula | K1: Total Clio cuspidata | L1: Total Clio pyramidata | M1: Total Cavolinia sp. | N1: Total Clionidarum | O1: Total | Q1: Creseis spp. | AO1: Age R396 x 1000 | AP1: Total Heliconoides inflatus | AQ1: Total Limacina trochiformis | AR1: Total Limacina retroversa | AS1: Creseis spp. | AT1: Total Cavolinia sp. | AU1: Total
A2: 9-105 | B2: 101 | C2: 10.298053 | D2: =Species!AC2/Total!$D2 -> 0.25 | E2: =Species!AD2/Total!$D2 -> 0.25 | F2: =Species!AE2/Total!$D2 -> 0 | G2: =Species!AF2/Total!$D2 -> 0 | H2: =Species!AG2/Total!$D2 -> 0 | I2: =Species!AH2/Total!$D2 -> 0 | J2: =Species!AI2/Total!$D2 -> 0 | K2: =Species!AJ2/Total!$D2 -> 0.25 | ... N2: =Species!AM2/Total!$D2 -> 0 | O2: =SUM(D2:N2) -> 1 | Q2: =SUM(H2:J2) -> 0 | AO2: 10.298053 | AP2: 1 | AQ2: 1 | AR2: 0 | AS2: =SUM(Species!N2:S2) -> 0 | AT2: 1 | AU2: =SUM(AP2:AT2) -> 3
A3: 9-015 | B3: 191 | C3: 11.768078 | D3: =Species!AC3/Total!$D3 -> 0.36986301 | E3: =Species!AD3/Total!$D3 -> 0.54794521 | F3: =Species!AE3/Total!$D3 -> 0.02739726 | G3: =Species!AF3/Total!$D3 -> 0 | H3: =Species!AG3/Total!$D3 -> 0 | I3: =Species!AH3/Total!$D3 -> 0.04109589 | J3: =Species!AI3/Total!$D3 -> 0 | K3: =Species!AJ3/Total!$D3 -> 0 | ... N3: =Species!AM3/Total!$D3 -> 0 | O3: =SUM(D3:N3) -> 1 | Q3: =SUM(H3:J3) -> 0.04109589 | AO3: 11.768078 | AP3: 27 | AQ3: 40 | AR3: 2 | AS3: =SUM(Species!N3:S3) -> 3 | AT3: 1 | AU3: =SUM(AP3:AT3) -> 73
A4: 8-145 | B4: 211 | C4: 12.140505 | D4: =Species!AC4/Total!$D4 -> 0.13559322 | E4: =Species!AD4/Total!$D4 -> 0.6440678 | F4: =Species!AE4/Total!$D4 -> 0.06779661 | G4: =Species!AF4/Total!$D4 -> 0 | H4: =Species!AG4/Total!$D4 -> 0 | I4: =Species!AH4/Total!$D4 -> 0.016949153 | J4: =Species!AI4/Total!$D4 -> 0.050847458 | K4: =Species!AJ4/Total!$D4 -> 0.016949153 | ... N4: =Species!AM4/Total!$D4 -> 0 | O4: =SUM(D4:N4) -> 1 | Q4: =SUM(H4:J4) -> 0.06779661 | AO4: 12.140505 | AP4: 8 | AQ4: 38 | AR4: 4 | AS4: =SUM(Species!N4:S4) -> 4 | AT4: 4 | AU4: =SUM(AP4:AT4) -> 58
A5: 8-075 | B5: 281 | C5: 12.681927 | D5: =Species!AC5/Total!$D5 -> 0.20689655 | E5: =Species!AD5/Total!$D5 -> 0.48275862 | F5: =Species!AE5/Total!$D5 -> 0.10344828 | G5: =Species!AF5/Total!$D5 -> 0 | H5: =Species!AG5/Total!$D5 -> 0 | I5: =Species!AH5/Total!$D5 -> 0.10344828 | J5: =Species!AI5/Total!$D5 -> 0 | K5: =Species!AJ5/Total!$D5 -> 0.034482759 | ... N5: =Species!AM5/Total!$D5 -> 0 | O5: =SUM(D5:N5) -> 1 | Q5: =SUM(H5:J5) -> 0.10344828 | AO5: 12.681927 | AP5: 6 | AQ5: 14 | AR5: 3 | AS5: =SUM(Species!N5:S5) -> 3 | AT5: 1 | AU5: =SUM(AP5:AT5) -> 27
A6: 8-020 | B6: 336 | C6: 12.90434 | D6: =Species!AC6/Total!$D6 -> 0.20338983 | E6: =Species!AD6/Total!$D6 -> 0.56779661 | F6: =Species!AE6/Total!$D6 -> 0.016949153 | G6: =Species!AF6/Total!$D6 -> 0.033898305 | H6: =Species!AG6/Total!$D6 -> 0 | I6: =Species!AH6/Total!$D6 -> 0.11864407 | J6: =Species!AI6/Total!$D6 -> 0.016949153 | K6: =Species!AJ6/Total!$D6 -> 0.025423729 | ... N6: =Species!AM6/Total!$D6 -> 0 | O6: =SUM(D6:N6) -> 1 | Q6: =SUM(H6:J6) -> 0.13559322 | AO6: 12.90434 | AP6: 24 | AQ6: 67 | AR6: 2 | AS6: =SUM(Species!N6:S6) -> 16 | AT6: 1 | AU6: =SUM(AP6:AT6) -> 110
A7: 7-025 | B7: 482 | C7: 13.4115 | D7: =Species!AC7/Total!$D7 -> 0.27777778 | E7: =Species!AD7/Total!$D7 -> 0.38888889 | F7: =Species!AE7/Total!$D7 -> 0.055555556 | G7: =Species!AF7/Total!$D7 -> 0 | H7: =Species!AG7/Total!$D7 -> 0 | I7: =Species!AH7/Total!$D7 -> 0.16666667 | J7: =Species!AI7/Total!$D7 -> 0 | K7: =Species!AJ7/Total!$D7 -> 0 | ... N7: =Species!AM7/Total!$D7 -> 0 | O7: =SUM(D7:N7) -> 1 | Q7: =SUM(H7:J7) -> 0.16666667 | AO7: 13.4115 | AP7: 5 | AQ7: 7 | AR7: 1 | AS7: =SUM(Species!N7:S7) -> 3 | AT7: 2 | AU7: =SUM(AP7:AT7) -> 18
A8: 6a-075 | B8: 542 | C8: 15.297745 | D8: =Species!AC8/Total!$D8 -> 0.67114094 | E8: =Species!AD8/Total!$D8 -> 0.13422819 | F8: =Species!AE8/Total!$D8 -> 0.080536913 | G8: =Species!AF8/Total!$D8 -> 0.0067114094 | H8: =Species!AG8/Total!$D8 -> 0.0067114094 | I8: =Species!AH8/Total!$D8 -> 0.067114094 | J8: =Species!AI8/Total!$D8 -> 0.0067114094 | K8: =Species!AJ8/Total!$D8 -> 0 | ... N8: =Species!AM8/Total!$D8 -> 0.0067114094 | O8: =SUM(D8:N8) -> 1 | Q8: =SUM(H8:J8) -> 0.080536913 | AO8: 15.297745 | AP8: 100 | AQ8: 20 | AR8: 12 | AS8: =SUM(Species!N8:S8) -> 12 | AT8: 3 | AU8: =SUM(AP8:AT8) -> 147
A9: 6a-010 | B9: 607 | C9: 17.630333 | D9: =Species!AC9/Total!$D9 -> 0.5625 | E9: =Species!AD9/Total!$D9 -> 0.3125 | F9: =Species!AE9/Total!$D9 -> 0 | G9: =Species!AF9/Total!$D9 -> 0 | H9: =Species!AG9/Total!$D9 -> 0 | I9: =Species!AH9/Total!$D9 -> 0 | J9: =Species!AI9/Total!$D9 -> 0.0625 | K9: =Species!AJ9/Total!$D9 -> 0 | ... N9: =Species!AM9/Total!$D9 -> 0 | O9: =SUM(D9:N9) -> 1 | Q9: =SUM(H9:J9) -> 0.0625 | AO9: 17.630333 | AP9: 9 | AQ9: 5 | AR9: 0 | AS9: =SUM(Species!N9:S9) -> 1 | AT9: 1 | AU9: =SUM(AP9:AT9) -> 16
A10: 6-125 | B10: 641 | C10: 19.789979 | D10: =Species!AC10/Total!$D10 -> 0.26470588 | E10: =Species!AD10/Total!$D10 -> 0.17647059 | F10: =Species!AE10/Total!$D10 -> 0.029411765 | G10: =Species!AF10/Total!$D10 -> 0 | H10: =Species!AG10/Total!$D10 -> 0.088235294 | I10: =Species!AH10/Total!$D10 -> 0.35294118 | J10: =Species!AI10/Total!$D10 -> 0 | K10: =Species!AJ10/Total!$D10 -> 0 | ... N10: =Species!AM10/Total!$D10 -> 0 | O10: =SUM(D10:N10) -> 1 | Q10: =SUM(H10:J10) -> 0.44117647 | AO10: 19.789979 | AP10: 9 | AQ10: 6 | AR10: 1 | AS10: =SUM(Species!N10:S10) -> 15 | AT10: 2 | AU10: =SUM(AP10:AT10) -> 33
A11: 6-090 | B11: 676 | C11: 22.102144 | D11: =Species!AC11/Total!$D11 -> 0.51612903 | E11: =Species!AD11/Total!$D11 -> 0.032258065 | F11: =Species!AE11/Total!$D11 -> 0.16129032 | G11: =Species!AF11/Total!$D11 -> 0 | H11: =Species!AG11/Total!$D11 -> 0 | I11: =Species!AH11/Total!$D11 -> 0.12903226 | J11: =Species!AI11/Total!$D11 -> 0 | K11: =Species!AJ11/Total!$D11 -> 0.032258065 | ... N11: =Species!AM11/Total!$D11 -> 0 | O11: =SUM(D11:N11) -> 1 | Q11: =SUM(H11:J11) -> 0.12903226 | AO11: 22.102144 | AP11: 16 | AQ11: 1 | AR11: 5 | AS11: =SUM(Species!N11:S11) -> 4 | AT11: 3 | AU11: =SUM(AP11:AT11) -> 29
A12: 6-020 | B12: 746 | C12: 26.142462 | D12: =Species!AC12/Total!$D12 -> 0.56287425 | E12: =Species!AD12/Total!$D12 -> 0.13173653 | F12: =Species!AE12/Total!$D12 -> 0.071856287 | G12: =Species!AF12/Total!$D12 -> 0.011976048 | H12: =Species!AG12/Total!$D12 -> 0.023952096 | I12: =Species!AH12/Total!$D12 -> 0.11976048 | J12: =Species!AI12/Total!$D12 -> 0.011976048 | K12: =Species!AJ12/Total!$D12 -> 0.011976048 | ... N12: =Species!AM12/Total!$D12 -> 0 | O12: =SUM(D12:N12) -> 1 | Q12: =SUM(H12:J12) -> 0.15568862 | AO12: 26.142462 | AP12: 94 | AQ12: 22 | AR12: 12 | AS12: =SUM(Species!N12:S12) -> 26 | AT12: 5 | AU12: =SUM(AP12:AT12) -> 159
A13: 4-060 | B13: 833 | C13: 29.476255 | D13: =Species!AC13/Total!$D13 -> 0 | E13: =Species!AD13/Total!$D13 -> 0.5 | F13: =Species!AE13/Total!$D13 -> 0 | G13: =Species!AF13/Total!$D13 -> 0 | H13: =Species!AG13/Total!$D13 -> 0 | I13: =Species!AH13/Total!$D13 -> 0.5 | J13: =Species!AI13/Total!$D13 -> 0 | K13: =Species!AJ13/Total!$D13 -> 0 | ... N13: =Species!AM13/Total!$D13 -> 0 | O13: =SUM(D13:N13) -> 1 | Q13: =SUM(H13:J13) -> 0.5 | AO13: 29.476255 | AP13: 0 | AQ13: 1 | AR13: 0 | AS13: =SUM(Species!N13:S13) -> 1 | AT13: 0 | AU13: =SUM(AP13:AT13) -> 2
A14: 4-005 | B14: 888 | C14: 30.863619 | D14: =Species!AC14/Total!$D14 -> 0.33333333 | E14: =Species!AD14/Total!$D14 -> 0 | F14: =Species!AE14/Total!$D14 -> 0 | G14: =Species!AF14/Total!$D14 -> 0 | H14: =Species!AG14/Total!$D14 -> 0.66666667 | I14: =Species!AH14/Total!$D14 -> 0 | J14: =Species!AI14/Total!$D14 -> 0 | K14: =Species!AJ14/Total!$D14 -> 0 | ... N14: =Species!AM14/Total!$D14 -> 0 | O14: =SUM(D14:N14) -> 1 | Q14: =SUM(H14:J14) -> 0.66666667 | AO14: 30.863619 | AP14: 1 | AQ14: 0 | AR14: 0 | AS14: =SUM(Species!N14:S14) -> 2 | AT14: 0 | AU14: =SUM(AP14:AT14) -> 3
A15: 3-031 | B15: 940 | C15: 31.496038 | D15: 0 | E15: 0 | F15: 0 | G15: 0 | H15: 0 | I15: 0 | J15: 0 | K15: 0 | L15: 0 | M15: 0 | N15: 0 | O15: =SUM(D15:N15) -> 0 | Q15: =SUM(H15:J15) -> 0 | AO15: 31.496038 | AP15: 0 | AQ15: 0 | AR15: 0 | AS15: =SUM(Species!N15:S15) -> 0 | AT15: 0 | AU15: =SUM(AP15:AT15) -> 0
A16: 2-025 | B16: 1021 | C16: 33.121 | D16: 0 | E16: 0 | F16: 0 | G16: 0 | H16: 0 | I16: 0 | J16: 0 | K16: 0 | L16: 0 | M16: 0 | N16: 0 | O16: =SUM(D16:N16) -> 0 | Q16: =SUM(H16:J16) -> 0 | AO16: 33.121 | AP16: 0 | AQ16: 0 | AR16: 0 | AS16: =SUM(Species!N16:S16) -> 0 | AT16: 0 | AU16: =SUM(AP16:AT16) -> 0
A17: Mean | D17: {=SUM(D2:D16/15)} -> 0.29028026 | E17: {=SUM(E2:E16/15)} -> 0.27791003 | F17: {=SUM(F2:F16/15)} -> 0.040949476 | G17: {=SUM(G2:G16/15)} -> 0.0035057175 | H17: {=SUM(H2:H16/15)} -> 0.052371031 | I17: {=SUM(I2:I16/15)} -> 0.10771014 | J17: {=SUM(J2:J16/15)} -> 0.0099322712 | K17: {=SUM(K2:K16/15)} -> 0.024739317 | ... N17: {=SUM(N2:N16/15)} -> 0.00044742729 | Q17: =SUM(H17:J17) -> 0.17001344 | AP17: 300 | AQ17: 222 | AR17: 42 | AS17: =SUM(Species!N17:S17) -> 90 | AT17: 24 | AU17: =SUM(AP17:AT17) -> 678
AO20: Age | AP20: H. inflatus | AQ20: L. trochiformis | AR20: L. retroversa | AS20: Creseis spp. | AT20: Cavolinia sp. | AU20: Total
AO21: 10.298053 | AP21: =AP2/AU2 -> 0.33333333 | AQ21: =AQ2/AU2 -> 0.33333333 | AR21: =AR2/AU2 -> 0 | AS21: =AS2/AU2 -> 0 | AT21: =AT2/AU2 -> 0.33333333
AO22: 11.768078 | AP22: =AP3/AU3 -> 0.36986301 | AQ22: =AQ3/AU3 -> 0.54794521 | AR22: =AR3/AU3 -> 0.02739726 | AS22: =AS3/AU3 -> 0.04109589 | AT22: =AT3/AU3 -> 0.01369863
AO23: 12.140505 | AP23: =AP4/AU4 -> 0.13793103 | AQ23: =AQ4/AU4 -> 0.65517241 | AR23: =AR4/AU4 -> 0.068965517 | AS23: =AS4/AU4 -> 0.068965517 | AT23: =AT4/AU4 -> 0.068965517
AO24: 12.681927 | AP24: =AP5/AU5 -> 0.22222222 | AQ24: =AQ5/AU5 -> 0.51851852 | AR24: =AR5/AU5 -> 0.11111111 | AS24: =AS5/AU5 -> 0.11111111 | AT24: =AT5/AU5 -> 0.037037037
AO25: 12.90434 | AP25: =AP6/AU6 -> 0.21818182 | AQ25: =AQ6/AU6 -> 0.60909091 | AR25: =AR6/AU6 -> 0.018181818 | AS25: =AS6/AU6 -> 0.14545455 | AT25: =AT6/AU6 -> 0.0090909091
AO26: 13.4115 | AP26: =AP7/AU7 -> 0.27777778 | AQ26: =AQ7/AU7 -> 0.38888889 | AR26: =AR7/AU7 -> 0.055555556 | AS26: =AS7/AU7 -> 0.16666667 | AT26: =AT7/AU7 -> 0.11111111
AO27: 15.297745 | AP27: =AP8/AU8 -> 0.68027211 | AQ27: =AQ8/AU8 -> 0.13605442 | AR27: =AR8/AU8 -> 0.081632653 | AS27: =AS8/AU8 -> 0.081632653 | AT27: =AT8/AU8 -> 0.020408163
AO28: 17.630333 | AP28: =AP9/AU9 -> 0.5625 | AQ28: =AQ9/AU9 -> 0.3125 | AR28: =AR9/AU9 -> 0 | AS28: =AS9/AU9 -> 0.0625 | AT28: =AT9/AU9 -> 0.0625
AO29: 19.789979 | AP29: =AP10/AU10 -> 0.27272727 | AQ29: =AQ10/AU10 -> 0.18181818 | AR29: =AR10/AU10 -> 0.03030303 | AS29: =AS10/AU10 -> 0.45454545 | AT29: =AT10/AU10 -> 0.060606061
AO30: 22.102144 | AP30: =AP11/AU11 -> 0.55172414 | AQ30: =AQ11/AU11 -> 0.034482759 | AR30: =AR11/AU11 -> 0.17241379 | AS30: =AS11/AU11 -> 0.13793103 | AT30: =AT11/AU11 -> 0.10344828
AO31: 26.142462 | AP31: =AP12/AU12 -> 0.59119497 | AQ31: =AQ12/AU12 -> 0.13836478 | AR31: =AR12/AU12 -> 0.075471698 | AS31: =AS12/AU12 -> 0.16352201 | AT31: =AT12/AU12 -> 0.031446541
AO32: 29.476255 | AP32: =AP13/AU13 -> 0 | AQ32: =AQ13/AU13 -> 0.5 | AR32: =AR13/AU13 -> 0 | AS32: =AS13/AU13 -> 0.5 | AT32: =AT13/AU13 -> 0
AO33: 30.863619 | AP33: =AP14/AU14 -> 0.33333333 | AQ33: =AQ14/AU14 -> 0 | AR33: =AR14/AU14 -> 0 | AS33: =AS14/AU14 -> 0.66666667 | AT33: =AT14/AU14 -> 0
AO34: 31.496038 | AP34: 0 | AQ34: 0 | AR34: 0 | AS34: 0 | AT34: 0
AO35: 33.121 | AP35: 0 | AQ35: 0 | AR35: 0 | AS35: 0 | AT35: 0

Sheet Plots

Sheet Stacked chart

Sheet Total + Sam
A1: Sample | B1: cmbs | C1: Age R396 x 1000 | D1: Pt counted | E1: Pt total | F1: Gram sediment | G1: Pt per gram sediment
A2: 10-055 | B2: 1 | C2: 8.7 | D2: 2 | E2: 2 | F2: 12.46 | G2: =ROUND(E2/F2,2) -> 0.16
A3: 9-140 | B3: 66 | C3: 9.74 | D3: 1 | E3: 1 | F3: 9.28 | G3: =ROUND(E3/F3,2) -> 0.11
A4: 9-105 | B4: 101 | C4: 10.298053 | D4: 4 | E4: 4 | F4: 8.26 | G4: =ROUND(E4/F4,2) -> 0.48
A5: 9-080 | B5: 126 | C5: 10.7 | D5: 9 | E5: 9 | F5: 10.36 | G5: =ROUND(E5/F5,2) -> 0.87
A6: 9-030 | B6: 176 | C6: 11.49 | D6: 18 | E6: 18 | F6: 9.88 | G6: =ROUND(E6/F6,2) -> 1.82
A7: 9-015 | B7: 191 | C7: 11.768078 | D7: 73 | E7: 73 | F7: 9.91 | G7: =ROUND(E7/F7,2) -> 7.37
A8: 8-145 | B8: 211 | C8: 12.140505 | D8: 59 | E8: 59 | F8: 12.13 | G8: =ROUND(E8/F8,2) -> 4.86
A9: 8-110 | B9: 246 | C9: 12.55 | D9: 70 | E9: 70 | F9: 13.78 | G9: =ROUND(E9/F9,2) -> 5.08
A10: 8-075 | B10: 281 | C10: 12.681927 | D10: 29 | E10: 99 | F10: 10.47 | G10: =ROUND(E10/F10,2) -> 9.46
A11: 8-040 | B11: 316 | C11: 12.82 | D11: 125 | E11: 533.33 | F11: 13.05 | G11: =ROUND(E11/F11,2) -> 40.87
A12: 8-020 | B12: 336 | C12: 12.90434 | D12: 118 | E12: 343.27 | F12: 13.45 | G12: =ROUND(E12/F12,2) -> 25.52
A13: 7-125 | B13: 382 | C13: 13.14 | D13: 8 | E13: 8 | F13: 14.06 | G13: =ROUND(E13/F13,2) -> 0.57
... A16: 7-025 | B16: 482 | C16: 13.4115 | D16: 18 | E16: 18 | F16: 13.7 | G16: =ROUND(E16/F16,2) -> 1.31
A17: 7-005 | B17: 502 | C17: 13.82 | D17: 189 | E17: 214 | F17: 17.07 | G17: =ROUND(E17/F17,2) -> 12.54 | I17: My data
A18: 6a-075 | B18: 542 | C18: 15.297745 | D18: 149 | E18: 1230.45 | F18: 13.66 | G18: =ROUND(E18/F18,2) -> 90.08 | I18: Sam Poelmans data
A19: 6a-057 | B19: 560 | C19: 15.99 | D19: 122 | E19: 1952 | F19: 14.15 | G19: =ROUND(E19/F19,2) -> 137.95
A20: 6a--025 | B20: 592 | C20: 17.29 | D20: 0 | E20: 0 | F20: 13.45 | G20: =ROUND(E20/F20,2) -> 0
A21: 6a-010 | B21: 607 | C21: 17.630333 | D21: 16 | E21: 16 | F21: 12.89 | G21: =ROUND(E21/F21,2) -> 1.24
A22: 6-125 | B22: 641 | C22: 19.789979 | D22: 34 | E22: 34 | F22: 12.82 | G22: =ROUND(E22/F22,2) -> 2.65
A23: 6-110 | B23: 656 | C23: 20.78 | D23: 7 | E23: 7 | F23: 16.21 | G23: =ROUND(E23/F23,2) -> 0.43
A24: 6-090 | B24: 676 | C24: 22.102144 | D24: 31 | E24: 31 | F24: 16.08 | G24: =ROUND(E24/F24,2) -> 1.93
A25: 6-070 | B25: 696 | C25: 23.42 | D25: 20 | E25: 20 | F25: 16.59 | G25: =ROUND(E25/F25,2) -> 1.21
A26: 6-030 | B26: 736 | C26: 25.21 | D26: 11 | E26: 11 | F26: 16.83 | G26: =ROUND(E26/F26,2) -> 0.65
A27: 6-020 | B27: 746 | C27: 26.142462 | D27: 167 | E27: 167 | F27: 19.41 | G27: =ROUND(E27/F27,2) -> 8.6
A28: 5-030 | B28: 799 | C28: 28.52 | D28: 1 | E28: 1 | F28: 13.8 | G28: =ROUND(E28/F28,2) -> 0.07
A29: 4-060 | B29: 833 | C29: 29.476255 | D29: 2 | E29: 2 | F29: 14.7 | G29: =ROUND(E29/F29,2) -> 0.14
A30: 4-022 | B30: 871 | C30: 30.55 | D30: 12 | E30: 12 | F30: 15.02 | G30: =ROUND(E30/F30,2) -> 0.8
... A35: 2-025 | B35: 1021 | C35: 33.121 | D35: 0 | E35: 0 | F35: 15.96 | G35: =ROUND(E35/F35,2) -> 0

Sheet Sedimentation speed
A1: Cmbs | B1: Median R396+/-50 | C1: Sedimentation rate | P1: Sample | Q1: Age_ka
A2: 7 | B2: 8.799 | C2: =ROUND((A3-A2)/(B3-B2),2) -> 62.71 | P2: 9-105 | Q2: 10.298053 | R2: =C2+(Q2-B2)/(B3-B2)*(C3-C2) -> 57.757135
A3: 178 | B3: 11.526 | C3: =ROUND((A4-A3)/(B4-B3),2) -> 53.7 | P3: 9-015 | Q3: 11.768078 | R3: =C3+(Q3-B3)/(B4-B3)*(C4-C3) -> 106.15942
A4: 229.5 | B4: 12.485 | C4: =ROUND((A5-A4)/(B5-B4),2) -> 261.52 | P4: 8-145 | Q4: 12.140505 | R4: =C3+(Q4-B3)/(B4-B3)*(C4-C3) -> 186.86621
A5: 326 | B5: 12.854 | C5: =ROUND((A6-A5)/(B6-B5),2) -> 198.65 | P5: 8-075 | Q5: 12.681927 | R5: =C4+(Q5-B4)/(B5-B4)*(C5-C4) -> 227.96762
A6: 399.5 | B6: 13.224 | C6: =ROUND((A7-A6)/(B7-B6),2) -> 684.93 | P6: 8-020 | Q6: 12.90434 | R6: =C5+(Q6-B5)/(B6-B5)*(C6-C5) -> 264.81055
A7: 449.5 | B7: 13.297 | C7: =ROUND((A8-A7)/(B8-B7),2) -> 556.6 | P7: 7-025 | Q7: 13.4115 | R7: =C8+(Q7-B8)/(B9-B8)*(C9-C8) -> 46.168846
A8: 479 | B8: 13.35 | C8: =ROUND((A9-A8)/(B9-B8),2) -> 48.78 | P8: 6a-075 | Q8: 15.297745 | R8: =C9+(Q8-B9)/(B10-B9)*(C10-C9) -> 27.455091
A9: 505 | B9: 13.883 | C9: =ROUND((A10-A9)/(B10-B9),2) -> 26.15 | P9: 6a-010 | Q9: 17.630333 | R9: =C12+(Q9-B12)/(B13-B12)*(C13-C12) -> 16.756667
A10: 560 | B10: 15.986 | C10: =ROUND((A11-A10)/(B11-B10),2) -> 28.09 | P10: 6-125 | Q10: 19.789979 | R10: =C13+(Q10-B13)/(B14-B13)*(C14-C13) -> 15.925361
A11: 570 | B11: 16.342 | C11: =ROUND((A12-A11)/(B12-B11),2) -> 13.87 | P11: 6-090 | Q11: 22.102144 | R11: =C13+(Q11-B13)/(B14-B13)*(C14-C13) -> 17.812474
A12: 579 | B12: 16.991 | C12: =ROUND((A13-A12)/(B13-B12),2) -> 52.55 | P12: 6-020 | Q12: 26.142462 | R12: =C14+(Q12-B14)/(B15-B14)*(C15-C14) -> 27.696667
A13: 615 | B13: 17.676 | C13: =ROUND((A14-A13)/(B14-B13),2) -> 14.2 | P13: 4-060 | Q13: 29.476255 | R13: =C15+(Q13-B15)/(B16-B15)*(C16-C15) -> 59.877979
A14: 706 | B14: 24.084 | C14: =ROUND((A15-A14)/(B15-B14),2) -> 19.43 | P14: 4-005 | Q14: 30.863619 | R14: =C17+(Q14-B17)/(B18-B17)*(C18-C17) -> 59.456511
A15: 784 | B15: 28.098 | C15: =ROUND((A16-A15)/(B16-B15),2) -> 35.55 | P15: 3-031 | Q15: 31.496038 | R15: =C16+(Q15-B16)/(B17-B16)*(C17-C16) -> 54.030666
A16: 878 | B16: 30.742 | C16: =ROUND((A17-A16)/(B17-B16),2) -> 82.22 | P16: 2-025 | Q16: 33.121
A17: 983 | B17: 32.019 | C17: =ROUND((A18-A17)/(B18-B17),2) -> 34.48
A18: 1038 | B18: 33.614

Sheet Aragonite%
A1: Sample | B1: cmbs | C1: Age R396 x 1000 | D1: Pt per gram sediment | E1: plf per gram sediment | F1: Aragonite/calcite ratio | G1: Aragonite %
A2: 9-105 | B2: 101 | C2: 10.298053 | D2: 0.48 | E2: 15 | F2: =ROUND(D2/E2,2) -> 0.03 | G2: =ROUND(D2/(D2+E2),2) -> 0.03
A3: 9-015 | B3: 191 | C3: 11.768078 | D3: 7.37 | E3: 41 | F3: =ROUND(D3/E3,2) -> 0.18 | G3: =ROUND(D3/(D3+E3),2) -> 0.15
A4: 8-145 | B4: 211 | C4: 12.140505 | D4: 4.86 | E4: 27 | F4: =ROUND(D4/E4,2) -> 0.18 | G4: =ROUND(D4/(D4+E4),2) -> 0.15
A5: 8-075 | B5: 281 | C5: 12.681927 | D5: 9.46 | E5: 43 | F5: =ROUND(D5/E5,2) -> 0.22 | G5: =ROUND(D5/(D5+E5),2) -> 0.18
A6: 8-020 | B6: 336 | C6: 12.90434 | D6: 25.52 | E6: 263 | F6: =ROUND(D6/E6,2) -> 0.1 | G6: =ROUND(D6/(D6+E6),2) -> 0.09
A7: 7-025 | B7: 482 | C7: 13.4115 | D7: 1.31 | E7: 240 | F7: =ROUND(D7/E7,2) -> 0.01 | G7: =ROUND(D7/(D7+E7),2) -> 0.01
A8: 6a-075 | B8: 542 | C8: 15.297745 | D8: 90.08 | E8: 534 | F8: =ROUND(D8/E8,2) -> 0.17 | G8: =ROUND(D8/(D8+E8),2) -> 0.14
A9: 6a-010 | B9: 607 | C9: 17.630333 | D9: 1.24 | E9: 70 | F9: =ROUND(D9/E9,2) -> 0.02 | G9: =ROUND(D9/(D9+E9),2) -> 0.02
A10: 6-125 | B10: 641 | C10: 19.789979 | D10: 2.65 | E10: 784 | F10: =ROUND(D10/E10,2) -> 0 | G10: =ROUND(D10/(D10+E10),2) -> 0
A11: 6-090 | B11: 676 | C11: 22.102144 | D11: 1.93 | E11: 1317 | F11: =ROUND(D11/E11,2) -> 0 | G11: =ROUND(D11/(D11+E11),2) -> 0
A12: 6-020 | B12: 746 | C12: 26.142462 | D12: 8.6 | E12: 368 | F12: =ROUND(D12/E12,2) -> 0.02 | G12: =ROUND(D12/(D12+E12),2) -> 0.02
A13: 4-060 | B13: 833 | C13: 29.476255 | D13: 0.14 | E13: 455 | F13: =ROUND(D13/E13,2) -> 0 | G13: =ROUND(D13/(D13+E13),2) -> 0
... A16: 2-025 | B16: 1021 | C16: 33.121 | D16: 0 | E16: 386 | F16: =ROUND(D16/E16,2) -> 0 | G16: =ROUND(D16/(D16+E16),2) -> 0

Sheet OMZ
A1: Depth sed (m) | B1: Age (ka BP) | C1: Globobulimina spp, Mg/Ca [mmol/mol] | D1: BWT [°C] | E1: BWT e [±] | F1: O2 [µmol/kg] | G1: O2 std e [±] | H1: Globobulimina spp, δ18O [‰ PDB] | I1: Globobulimina spp, δ13C [‰ PDB] | J1: C, wuellerstorfi δ18O [‰ PDB] | K1: C, wuellerstorfi δ13C [‰ PDB] | L1: Forams upw [%] | N1: Data from https://doi,org/10,1029/2025PA005268 | V1: Sample | W1: Age_ka | X1: Interpolated O2 [µmol/kg]
A2: 0.03 | B2: 2.17 | C2: 4.8 | D2: 7.16 | E2: 0.7 | F2: 88.64 | G2: 17.38 | H2: 2.42 | I2: -0.42 | J2: 1.63 | K2: 0.65 | L2: 43.01 | N2: At 386 m water depth from core GeoB20911‐1 | V2: 9-105 | W2: 10.298053 | X2: =F9+(W2-B9)/(B10-B9)*(F10-F9) -> 68.882351
A3: 0.08 | B3: 3.32 | C3: 4.37 | D3: 5.97 | E3: 0.66 | F3: 46.45 | G3: 17.38 | H3: 3.03 | I3: 0.1 | J3: 1.84 | K3: 0.71 | V3: 9-015 | W3: 11.768078 | X3: =F10+(W3-B10)/(B11-B10)*(F11-F10) -> 87.502025
A4: 0.13 | B4: 4.47 | J4: 1.8 | K4: 0.7 | L4: 43.93 | V4: 8-145 | W4: 12.140505 | X4: =F10+(W4-B10)/(B10-B11)*(F10-F11) -> 71.779121
A5: 0.18 | B5: 5.62 | C5: 5.08 | D5: 7.94 | E5: 0.72 | F5: 33.45 | G5: 17.38 | H5: 2.51 | I5: 0.26 | J5: 1.92 | K5: 0.72 | V5: 8-075 | W5: 12.681927 | X5: =F11+(W5-B11)/(B12-B11)*(F12-F11) -> 67.331973
A6: 0.23 | B6: 6.77 | C6: 4.83 | D6: 7.25 | E6: 0.7 | F6: 40.73 | G6: 17.38 | H6: 2.22 | I6: 0.16 | J6: 1.75 | K6: 0.71 | L6: 44.59 | V6: 8-020 | W6: 12.90434 | X6: =F11+(W6-B11)/(B12-B11)*(F12-F11) -> 81.758639
A7: 0.28 | B7: 7.91 | C7: 5.17 | D7: 8.19 | E7: 0.73 | F7: 24.18 | G7: 17.38 | H7: 3.6 | I7: 0.03 | J7: 2.28 | K7: 0.39 | V7: 7-025 | W7: 13.4115 | X7: =F12+(W7-B12)/(B13-B12)*(F13-F12) -> 78.611017
A8: 0.33 | B8: 9.06 | C8: 5.64 | D8: 9.49 | E8: 0.78 | F8: 60.45 | G8: 17.38 | H8: 2.54 | I8: -0.14 | J8: 1.89 | K8: 0.62 | L8: 50 | V8: 6a-075 | W8: 15.297745 | X8: =F15+(W8-B15)/(B16-B15)*(F16-F15) -> 102.90054
A9: 0.38 | B9: 10.21 | C9: 5.67 | D9: 9.58 | E9: 0.78 | F9: 65.91 | G9: 17.38 | H9: 2.75 | I9: -0.35 | J9: 1.73 | K9: 0.47 | L9: 55.89 | V9: 6a-010 | W9: 17.630333 | X9: =F18+(W9-B18)/(B19-B18)*(F19-F18) -> 83.836861
A10: 0.43 | B10: 11.36 | C10: 4.45 | D10: 6.19 | E10: 0.67 | F10: 104.73 | G10: 17.38 | H10: 3.04 | I10: -0.67 | J10: 2.07 | K10: 0.58 | L10: 56.82 | V10: 6-125 | W10: 19.789979 | X10: =F21+(W10-B21)/(B22-B21)*(F22-F21) -> 45.103278
A11: 0.48 | B11: 12.51 | C11: 5.62 | D11: 9.44 | E11: 0.78 | F11: 56.18 | G11: 17.38 | H11: 2.61 | I11: -0.07 | J11: 1.73 | K11: 0.64 | L11: 57.39 | V11: 6-090 | W11: 22.102144 | X11: =F22+(W11-B22)/(B24-B22)*(F24-F22) -> 93.43712
A12: 0.53 | B12: 13.1 | F12: 94.45 | G12: 17.38 | H12: 3.65 | I12: -0.36 | J12: 2.6 | K12: 0.77 | L12: 44.83 | V12: 6-020 | W12: 26.142462 | X12: =F26+(W12-B26)/(B29-B26)*(F29-F26) -> 145.87369
A13: 0.58 | B13: 13.69 | C13: 5.37 | D13: 8.75 | E13: 0.75 | F13: 64.45 | G13: 17.38 | H13: 3.66 | I13: 0.04 | J13: 2.42 | K13: 0.84 | V13: 4-060 | W13: 29.476255 | X13: =F32+(W13-B32)/(B33-B32)*(F33-F32) -> 105.29447
A14: 0.63 | B14: 14.28 | C14: 5.98 | D14: 10.45 | E14: 0.82 | F14: 110.27 | G14: 17.38 | H14: 3.33 | I14: -0.64 | J14: 1.93 | K14: 0.67 | L14: 55.41 | V14: 4-005 | W14: 30.863619 | X14: =F33+(W14-B33)/(B35-B33)*(F35-F33) -> 141.08744
A15: 0.68 | B15: 14.88 | C15: 5.59 | D15: 9.37 | E15: 0.77 | F15: 112.36 | G15: 17.38 | H15: 3.33 | I15: -0.71 | J15: 2.24 | K15: 0.62 | V15: 3-031 | W15: 31.496038 | X15: =F35+(W15-B35)/(B36-B35)*(F36-F35) -> 142.54254
A16: 0.73 | B16: 15.47 | C16: 5.76 | D16: 9.84 | E16: 0.79 | F16: 99 | G16: 17.38 | H16: 3.72 | I16: -0.71 | J16: 2.1 | K16: 0.48 | L16: 49.2 | V16: 2-025 | W16: 33.121 | X16: =F36+(W16-B36)/(B37-B36)*(F37-F36) -> 172.962
A17: 0.78 | B17: 16.31 | C17: 5.14 | D17: 8.1 | E17: 0.73 | F17: 31.27 | G17: 17.38 | H17: 2.56 | I17: 0.34 | J17: 2.36 | K17: 0.78
A18: 0.83 | B18: 17.15 | C18: 4.74 | D18: 6.99 | E18: 0.69 | F18: 88.36 | G18: 17.38 | H18: 3.65 | I18: -0.48 | J18: 1.7 | K18: 0.58 | L18: 54.84
A19: 0.88 | B19: 17.99 | C19: 4.89 | D19: 7.43 | E19: 0.71 | F19: 80.45 | G19: 17.38 | H19: 3.13 | I19: -0.25 | J19: 2.16 | K19: 0.73
A20: 0.93 | B20: 18.84 | C20: 5.31 | D20: 8.58 | E20: 0.75 | F20: 32 | G20: 17.38 | H20: 3.73 | I20: -0.05 | J20: 2.02 | K20: 0.4 | L20: 44.44
A21: 0.98 | B21: 19.68 | C21: 4.7 | D21: 6.88 | E21: 0.69 | F21: 42.27 | G21: 17.38 | H21: 3.63 | I21: 0.11 | J21: 2.04 | K21: 0.67
A22: 1.03 | B22: 20.52 | C22: 5.09 | D22: 7.97 | E22: 0.72 | F22: 63.91 | G22: 17.38 | H22: 3.58 | I22: -0.22 | J22: 2.04 | K22: 0.57 | L22: 48.85
A23: 1.08 | B23: 21.36 | H23: 3.72 | I23: -0.39
A24: 1.13 | B24: 22.21 | C24: 5.31 | D24: 8.58 | E24: 0.75 | F24: 95.45 | G24: 17.38 | H24: 3.66 | I24: -0.64 | J24: 1.87 | K24: 0.5 | L24: 61.51
A25: 1.18 | B25: 23.05 | C25: 5.07 | D25: 7.93 | E25: 0.72 | H25: 3.77 | I25: -1.02
A26: 1.23 | B26: 23.89 | C26: 5.25 | D26: 8.41 | E26: 0.74 | F26: 77 | G26: 17.38 | H26: 3.43 | I26: -0.5 | J26: 1.8 | K26: 0.44 | L26: 57.14
A27: 1.28 | B27: 24.73 | H27: 3.18 | I27: -1.41
A28: 1.33 | B28: 25.58 | C28: 5.49 | D28: 9.08 | E28: 0.76 | H28: 3.56 | I28: -1.95 | L28: 53.56
A29: 1.38 | B29: 26.42 | C29: 5.58 | D29: 9.33 | E29: 0.77 | F29: 154.36 | G29: 17.38 | H29: 3.58 | I29: -0.92 | J29: 2.48 | K29: 0.88
A30: 1.43 | B30: 27.26 | C30: 6.23 | D30: 11.15 | E30: 0.84 | H30: 3.42 | I30: -0.02 | L30: 65.79
A31: 1.48 | B31: 28.1 | C31: 5.2 | D31: 8.27 | E31: 0.73 | F31: 163.36 | G31: 17.38 | H31: 3.14 | I31: -1.31 | J31: 2.08 | K31: 0.58
A32: 1.53 | B32: 28.95 | C32: 5.89 | D32: 10.21 | E32: 0.81 | F32: 53.64 | G32: 17.38 | H32: 3.54 | I32: 0.1 | J32: 2.8 | K32: 0.78 | L32: 54.52
A33: 1.58 | B33: 29.79 | C33: 5.55 | D33: 9.25 | E33: 0.77 | F33: 136.09 | G33: 17.38 | H33: 3.65 | I33: -0.88 | J33: 2.47 | K33: 0.72
A34: 1.63 | B34: 30.63 | C34: 5.08 | D34: 7.94 | E34: 0.72 | H34: 3.45 | I34: -0.76 | L34: 57.14
A35: 1.68 | B35: 31.47 | C35: 4.97 | D35: 7.65 | E35: 0.71 | F35: 143.91 | G35: 17.38 | H35: 3.44 | I35: -1.27 | J35: 2.07 | K35: 0.41
A36: 1.73 | B36: 32.32 | C36: 5.09 | D36: 7.96 | E36: 0.72 | F36: 99.27 | G36: 17.38 | H36: 3.54 | I36: -0.67 | J36: 1.91 | K36: 0.52 | L36: 63.11
A37: 1.78 | B37: 33.16 | C37: 5.32 | D37: 8.62 | E37: 0.75 | F37: 176.55 | G37: 17.38 | H37: 3.67 | I37: -1.66 | J37: 2.26 | K37: 0.38
A38: 1.83 | B38: 34 | C38: 5.34 | D38: 8.67 | E38: 0.75 | F38: 124.18 | G38: 17.38 | H38: 3.58 | I38: -0.94 | J38: 2.48 | K38: 0.52 | L38: 54.57
A39: 1.88 | B39: 34.84 | C39: 4.86 | D39: 7.33 | E39: 0.7 | F39: 55.18 | G39: 17.38 | H39: 3.14 | I39: 0.01 | J39: 1.98 | K39: 0.71
